Workbook

Sheet Dashboard
B2: DASHBOARD COMERCIAL INMOBILIARIO - CSO ( Chief Sales Manager)
B3: Control de ventas, embudo, fuentes, visitas, separaciones, facturación y proyecciones. Edita las fechas para analizar cualquier semana o periodo.
B5: Fecha inicio | C5: 45930 | D5: Fecha fin | E5: 46295 | L5: Fecha actual | O5: =TODAY() -> 46294
B7: 1. RESULTADOS COMERCIALES
B9: Meta vs Resultados | F9: Unidades
B10: Meta | D10: =SUMPRODUCT(Meta!$B$5:$B1136*IF(EOMONTH(Meta!$A$5:$A1136,0)<$C$5,0,IF(Meta!$A$5:$A1136>$E$5,0,(IF(EOMONTH(Meta!$A$5:$A1136,0)<$E$5,EOMONTH(Meta!$A$5:$A1136,0),$E$5)-IF(Meta!$A$5:$A1136>$C$5,Meta!$A$5:$A1136,$C$5)+1)/DAY(EOMONTH(Meta!$A$5:$A1136,0))))) -> 3600000 | F10: =SUMPRODUCT(Meta!$C$5:$C1136*IF(EOMONTH(Meta!$A$5:$A1136,0)<$C$5,0,IF(Meta!$A$5:$A1136>$E$5,0,(IF(EOMONTH(Meta!$A$5:$A1136,0)<$E$5,EOMONTH(Meta!$A$5:$A1136,0),$E$5)-IF(Meta!$A$5:$A1136>$C$5,Meta!$A$5:$A1136,$C$5)+1)/DAY(EOMONTH(Meta!$A$5:$A1136,0))))) -> 90
B11: Ventas Reales | D11: =SUMIFS(Data_Ventas!$N$2:$N1136,Data_Ventas!$A$2:$A1136,">="&$C$5,Data_Ventas!$A$2:$A1136,"<="&$E$5,Data_Ventas!$H$2:$H1136,"Venta") -> 742424.5 | F11: =COUNTIFS(Data_Ventas!$A$2:$A1136,">="&$C$5,Data_Ventas!$A$2:$A1136,"<="&$E$5,Data_Ventas!$H$2:$H1136,"Venta") -> 14
B12: Separaciones | D12: =SUMIFS(Data_Ventas!$N$2:$N1136,Data_Ventas!$A$2:$A1136,">="&$C$5,Data_Ventas!$A$2:$A1136,"<="&$E$5,Data_Ventas!$H$2:$H1136,"Separado") -> 0 | F12: =COUNTIFS(Data_Ventas!$A$15:$A1136,">="&$C$5,Data_Ventas!$A$15:$A1136,"<="&$E$5,Data_Ventas!$H$15:$H1136,"Separado") -> 0
B13: Bolsa cotizaciones | D13: =SUMIFS(Data_Cotiz!$N$2:$N1136,Data_Cotiz!$A$2:$A1136,">="&$C$5,Data_Cotiz!$A$2:$A1136,"<="&$E$5,Data_Cotiz!$H$2:$H1136,"En Cotizacion") -> 0 | F13: =COUNTIFS(Data_Ventas!$A$15:$A1136,">="&$C$5,Data_Ventas!$A$15:$A1136,"<="&$E$5,Data_Ventas!$H$15:$H1136,"En cotizacion") -> 0
B14: Pipeline Ponderado | D14: =SUMIFS(Data_Cotiz!$N$2:$N1136,Data_Cotiz!$A$2:$A1136,">="&$C$5,Data_Cotiz!$A$2:$A1136,"<="&$E$5,Data_Cotiz!$H$2:$H1136,"Listo para comprar") -> 0 | F14: =COUNTIFS(Data_Ventas!$A$15:$A1136,">="&$C$5,Data_Ventas!$A$15:$A1136,"<="&$E$5,Data_Ventas!$H$15:$H1136,"Listo para comprar") -> 0
B15: Forecast cierre | D15: =D11+D12+D14 -> 742424.5 | F15: =F11+F12+F14 -> 14
B16: Gap | D16: =D15-D10 -> -2857575.5
B18: cumplimiento de ventas | D18: =$D$11/$D$10 -> 0.20622903
B19: Indice Cumplimiento ventas | D19: =($D$11/$D$10)*100 -> 20.622903
B21: Facturacion Acumulada
B22: Periodo | D22: Facturación Acum.
B23: Semana actual | D23: =SUMIFS(Data_Ventas!$N$2:$N1136,Data_Ventas!$A$2:$A1136,">="&($E$5-WEEKDAY($E$5,2)+1),Data_Ventas!$A$2:$A1136,"<="&($E$5-WEEKDAY($E$5,2)+7)) -> 0
B24: Mes actual | D24: =SUMIFS(Data_Ventas!$N$2:$N1136,Data_Ventas!$A$2:$A1136,">="&DATE(YEAR($E$5),MONTH($E$5),1),Data_Ventas!$A$2:$A1136,"<="&EOMONTH($E$5,0)) -> 80000
B25: Trimestre actual | D25: =SUMIFS(Data_Ventas!$N$2:$N1136,Data_Ventas!$A$2:$A1136,">="&DATE(YEAR($E$5),3*INT((MONTH($E$5)-1)/3)+1,1),Data_Ventas!$A$2:$A1136,"<="&EOMONTH(DATE(YEAR($E$5),3*INT((MONTH($E$5)-1)/3)+1,1),2)) -> 247000
B26: Semestre actual | D26: =SUMIFS(Data_Ventas!$N$2:$N1136,Data_Ventas!$A$2:$A1136,">="&DATE(YEAR($E$5),IF(MONTH($E$5)<=6,1,7),1),Data_Ventas!$A$2:$A1136,"<="&EOMONTH(DATE(YEAR($E$5),IF(MONTH($E$5)<=6,1,7),1),5)) -> 247000
B27: Año actual | D27: =SUMIFS(Data_Ventas!$N$2:$N1136,Data_Ventas!$A$2:$A1136,">="&DATE(YEAR($E$5),1,1),Data_Ventas!$A$2:$A1136,"<="&DATE(YEAR($E$5),12,31)) -> 595160
B29: 2. MIX CONTADO/ FINANCIADO, CASH-IN, PRECIO, DESCUENTOS
B31: Tipo de compra
B32: Tipo | C32: Unidades | D32: % Unid | E32: Venta S/ | G32: ticket prom. | H32: % Vent
B33: Contado | C33: =COUNTIFS(Data_Ventas!$A$2:$A1136,">="&$C$5,Data_Ventas!$A$2:$A1136,"<="&$E$5,Data_Ventas!$H$2:$H1136,"Venta",Data_Ventas!$Q$2:$Q1136,B33) -> 2 | D33: =C33/$C$35 -> 0.14285714 | E33: =SUMIFS(Data_Ventas!$N$2:$N1136,Data_Ventas!$A$2:$A1136,">="&$C$5,Data_Ventas!$A$2:$A1136,"<="&$E$5,Data_Ventas!$H$2:$H1136,"Venta",Data_Ventas!$Q$2:$Q1136,B33) -> 103360 | G33: =IFERROR($E$33/$C$33,0) -> 51680 | H33: =E33/$E$35 -> 0.13921954
B34: Financiado | C34: =COUNTIFS(Data_Ventas!$A$2:$A1136,">="&$C$5,Data_Ventas!$A$2:$A1136,"<="&$E$5,Data_Ventas!$H$2:$H1136,"Venta",Data_Ventas!$Q$2:$Q1136,B34) -> 12 | D34: =C34/$C$35 -> 0.85714286 | E34: =SUMIFS(Data_Ventas!$N$2:$N1136,Data_Ventas!$A$2:$A1136,">="&$C$5,Data_Ventas!$A$2:$A1136,"<="&$E$5,Data_Ventas!$H$2:$H1136,"Venta",Data_Ventas!$Q$2:$Q1136,B34) -> 639064.5 | G34: =$E$34/$C$34 -> 53255.375 | H34: =E34/$E$35 -> 0.86078046
B35: Total | C35: =SUM(C33:C34) -> 14 | D35: =SUM(D33:D34) -> 1 | E35: =SUM(E33:E34) -> 742424.5 | H35: =SUM(H33:H34) -> 1
B37: Saldo financiado generado | D37: =E34-D41 -> 554014.5 | F37: =D37/D11 -> 0.74622335
B39: Cash-in comercial
B40: Tipo | D40: Cash-in venta | F40: Cash-in %
B41: Iniciales cobradas financiado | D41: =SUMIFS(Data_Ventas!$R$2:$R1136,Data_Ventas!$A$2:$A1136,">="&$C$5,Data_Ventas!$A$2:$A1136,"<="&$E$5,Data_Ventas!$H$2:$H1136,"Venta",Data_Ventas!$Q$2:$Q1136,B34) -> 85050 | F41: =D41/D11 -> 0.1145571
B42: ventas contados | D42: =SUMIFS(Data_Ventas!$R$2:$R1136,Data_Ventas!$A$2:$A1136,">="&$C$5,Data_Ventas!$A$2:$A1136,"<="&$E$5,Data_Ventas!$H$2:$H1136,"Venta",Data_Ventas!$Q$2:$Q1136,B33) -> 103360 | F42: =D42/D10 -> 0.028711111
B43: cash-in total | D43: =SUM(D41:D42) -> 188410
B45: cash-in por lote | D45: =$D$60/$C$35 -> 13457.857
B46: Inicial promedio S/. | D46: =$D$41/$C$34 -> 7087.5
B48: Descuentos
B49: Ventas a precios lista | D49: =SUMIFS(Data_Ventas!$M$2:$M1136,Data_Ventas!$A$2:$A1136,">="&$C$5,Data_Ventas!$A$2:$A1136,"<="&$E$5,Data_Ventas!$H$2:$H1136,"Venta") -> 742424.5
B50: Descuentos totales | D50: =SUMIFS(Data_Ventas!$O$2:$O1136,Data_Ventas!$A$2:$A1136,">="&$C$5,Data_Ventas!$A$2:$A1136,"<="&$E$5,Data_Ventas!$H$2:$H1136,"Venta") -> 0
B51: Descuento promedio | D51: =D50/F11 -> 0
B52: proteccion del precio % | D52: =D11/D49 -> 1
...

Sheet Meta
A1: PLAN CSO — META, PRESUPUESTO, FORECAST, CASH-IN Y PRECISIÓN
N3: Resultados Proyectados
A4: Mes | B4: Meta venta S/ | C4: Meta lotes | D4: Meta cash-in S/ | E4: Presupuesto CSO | F4: Presupuesto CMO | G4: Eventos plan | H4: Forecast S/ | I4: Venta real S/ | J4: Lotes real | K4: Cash-in real | L4: Forecast accuracy | M4: Gap vs meta | N4: Lead | O4: Agenda | P4: Visitas | Q4: Separaciones | R4: Estado
A5: 46023 | B5: 400000 | C5: 10 | D5: 175000 | E5: 65000 | F5: 43000 | G5: 4 | H5: =SUMIFS(Data_Ventas!$N:$N,Data_Ventas!$A:$A,">="&$A5,Data_Ventas!$A:$A,"<="&EOMONTH($A5,0),Data_Ventas!$H:$H,"Separado")+I5+SUMIFS(Data_Cotiz!$N:$N,Data_Cotiz!$A:$A,">="&$A5,Data_Cotiz!$A:$A,"<="&EOMONTH($A5,0),Data_Cotiz!$H:$H,"Listo para comprar") -> 244800 | I5: =SUMIFS(Data_Ventas!$N:$N,Data_Ventas!$A:$A,">="&$A5,Data_Ventas!$A:$A,"<="&EOMONTH($A5,0),Data_Ventas!$H:$H,"Venta") -> 244800 | J5: =COUNTIFS(Data_Ventas!$A:$A,">="&$A5,Data_Ventas!$A:$A,"<="&EOMONTH($A5,0),Data_Ventas!$H:$H,"Venta") -> 4 | K5: =SUMIFS(Data_Ventas!$R:$R,Data_Ventas!$A:$A,">="&$A5,Data_Ventas!$A:$A,"<="&EOMONTH($A5,0),Data_Ventas!$H:$H,"Venta") -> 27200 | L5: =IF(OR(H5="",I5="",I5=0),"",MAX(1-ABS(H5-I5)/I5)) -> 1 | M5: =IF(H5="","",H5-B5) -> -155200 | N5: =ROUNDUP(O5/Configuracion!$B$11,0) -> 325 | O5: =ROUNDUP(P5/Configuracion!$B$12,0) -> 65 | P5: =ROUNDUP(Q5/Configuracion!$B$13,0) -> 39 | Q5: =ROUNDUP(C5/Configuracion!$B$14,0) -> 13
A6: 46054 | B6: 400000 | C6: 10 | D6: 175000 | E6: 65000 | F6: 43000 | G6: 4 | H6: =SUMIFS(Data_Ventas!$N:$N,Data_Ventas!$A:$A,">="&$A6,Data_Ventas!$A:$A,"<="&EOMONTH($A6,0),Data_Ventas!$H:$H,"Separado")+I6+SUMIFS(Data_Cotiz!$N:$N,Data_Cotiz!$A:$A,">="&$A6,Data_Cotiz!$A:$A,"<="&EOMONTH($A6,0),Data_Cotiz!$H:$H,"Listo para comprar") -> 52360 | I6: =SUMIFS(Data_Ventas!$N:$N,Data_Ventas!$A:$A,">="&$A6,Data_Ventas!$A:$A,"<="&EOMONTH($A6,0),Data_Ventas!$H:$H,"Venta") -> 52360 | J6: =COUNTIFS(Data_Ventas!$A:$A,">="&$A6,Data_Ventas!$A:$A,"<="&EOMONTH($A6,0),Data_Ventas!$H:$H,"Venta") -> 1 | K6: =SUMIFS(Data_Ventas!$R:$R,Data_Ventas!$A:$A,">="&$A6,Data_Ventas!$A:$A,"<="&EOMONTH($A6,0),Data_Ventas!$H:$H,"Venta") -> 52360 | L6: =IF(OR(H6="",I6="",I6=0),"",MAX(1-ABS(H6-I6)/I6)) -> 1 | M6: =IF(H6="","",H6-B6) -> -347640 | N6: =ROUNDUP(O6/Configuracion!$B$11,0) -> 325 | O6: =ROUNDUP(P6/Configuracion!$B$12,0) -> 65 | P6: =ROUNDUP(Q6/Configuracion!$B$13,0) -> 39 | Q6: =ROUNDUP(C6/Configuracion!$B$14,0) -> 13
A7: 46082 | B7: 400000 | C7: 10 | D7: 175000 | E7: 65000 | F7: 43000 | G7: 4 | H7: =SUMIFS(Data_Ventas!$N:$N,Data_Ventas!$A:$A,">="&$A7,Data_Ventas!$A:$A,"<="&EOMONTH($A7,0),Data_Ventas!$H:$H,"Separado")+I7+SUMIFS(Data_Cotiz!$N:$N,Data_Cotiz!$A:$A,">="&$A7,Data_Cotiz!$A:$A,"<="&EOMONTH($A7,0),Data_Cotiz!$H:$H,"Listo para comprar") -> 51000 | I7: =SUMIFS(Data_Ventas!$N:$N,Data_Ventas!$A:$A,">="&$A7,Data_Ventas!$A:$A,"<="&EOMONTH($A7,0),Data_Ventas!$H:$H,"Venta") -> 51000 | J7: =COUNTIFS(Data_Ventas!$A:$A,">="&$A7,Data_Ventas!$A:$A,"<="&EOMONTH($A7,0),Data_Ventas!$H:$H,"Venta") -> 1 | K7: =SUMIFS(Data_Ventas!$R:$R,Data_Ventas!$A:$A,">="&$A7,Data_Ventas!$A:$A,"<="&EOMONTH($A7,0),Data_Ventas!$H:$H,"Venta") -> 51000 | L7: =IF(OR(H7="",I7="",I7=0),"",MAX(1-ABS(H7-I7)/I7)) -> 1 | M7: =IF(H7="","",H7-B7) -> -349000 | N7: =ROUNDUP(O7/Configuracion!$B$11,0) -> 325 | O7: =ROUNDUP(P7/Configuracion!$B$12,0) -> 65 | P7: =ROUNDUP(Q7/Configuracion!$B$13,0) -> 39 | Q7: =ROUNDUP(C7/Configuracion!$B$14,0) -> 13
A8: 46113 | B8: 400000 | C8: 10 | D8: 175000 | E8: 65000 | F8: 43000 | G8: 4 | H8: =SUMIFS(Data_Ventas!$N:$N,Data_Ventas!$A:$A,">="&$A8,Data_Ventas!$A:$A,"<="&EOMONTH($A8,0),Data_Ventas!$H:$H,"Separado")+I8+SUMIFS(Data_Cotiz!$N:$N,Data_Cotiz!$A:$A,">="&$A8,Data_Cotiz!$A:$A,"<="&EOMONTH($A8,0),Data_Cotiz!$H:$H,"Listo para comprar") -> 0 | I8: =SUMIFS(Data_Ventas!$N:$N,Data_Ventas!$A:$A,">="&$A8,Data_Ventas!$A:$A,"<="&EOMONTH($A8,0),Data_Ventas!$H:$H,"Venta") -> 0 | J8: =COUNTIFS(Data_Ventas!$A:$A,">="&$A8,Data_Ventas!$A:$A,"<="&EOMONTH($A8,0),Data_Ventas!$H:$H,"Venta") -> 0 | K8: =SUMIFS(Data_Ventas!$R:$R,Data_Ventas!$A:$A,">="&$A8,Data_Ventas!$A:$A,"<="&EOMONTH($A8,0),Data_Ventas!$H:$H,"Venta") -> 0 | L8: =IF(OR(H8="",I8="",I8=0),"",MAX(1-ABS(H8-I8)/I8)) | M8: =IF(H8="","",H8-B8) -> -400000 | N8: =ROUNDUP(O8/Configuracion!$B$11,0) -> 325 | O8: =ROUNDUP(P8/Configuracion!$B$12,0) -> 65 | P8: =ROUNDUP(Q8/Configuracion!$B$13,0) -> 39 | Q8: =ROUNDUP(C8/Configuracion!$B$14,0) -> 13
A9: 46143 | B9: 400000 | C9: 10 | D9: 175000 | E9: 65000 | F9: 43000 | G9: 4 | H9: =SUMIFS(Data_Ventas!$N:$N,Data_Ventas!$A:$A,">="&$A9,Data_Ventas!$A:$A,"<="&EOMONTH($A9,0),Data_Ventas!$H:$H,"Separado")+I9+SUMIFS(Data_Cotiz!$N:$N,Data_Cotiz!$A:$A,">="&$A9,Data_Cotiz!$A:$A,"<="&EOMONTH($A9,0),Data_Cotiz!$H:$H,"Listo para comprar") -> 0 | I9: =SUMIFS(Data_Ventas!$N:$N,Data_Ventas!$A:$A,">="&$A9,Data_Ventas!$A:$A,"<="&EOMONTH($A9,0),Data_Ventas!$H:$H,"Venta") -> 0 | J9: =COUNTIFS(Data_Ventas!$A:$A,">="&$A9,Data_Ventas!$A:$A,"<="&EOMONTH($A9,0),Data_Ventas!$H:$H,"Venta") -> 0 | K9: =SUMIFS(Data_Ventas!$R:$R,Data_Ventas!$A:$A,">="&$A9,Data_Ventas!$A:$A,"<="&EOMONTH($A9,0),Data_Ventas!$H:$H,"Venta") -> 0 | L9: =IF(OR(H9="",I9="",I9=0),"",MAX(1-ABS(H9-I9)/I9)) | M9: =IF(H9="","",H9-B9) -> -400000 | N9: =ROUNDUP(O9/Configuracion!$B$11,0) -> 325 | O9: =ROUNDUP(P9/Configuracion!$B$12,0) -> 65 | P9: =ROUNDUP(Q9/Configuracion!$B$13,0) -> 39 | Q9: =ROUNDUP(C9/Configuracion!$B$14,0) -> 13
A10: 46174 | B10: 400000 | C10: 10 | D10: 175000 | E10: 65000 | F10: 43000 | G10: 4 | H10: =SUMIFS(Data_Ventas!$N:$N,Data_Ventas!$A:$A,">="&$A10,Data_Ventas!$A:$A,"<="&EOMONTH($A10,0),Data_Ventas!$H:$H,"Separado")+I10+SUMIFS(Data_Cotiz!$N:$N,Data_Cotiz!$A:$A,">="&$A10,Data_Cotiz!$A:$A,"<="&EOMONTH($A10,0),Data_Cotiz!$H:$H,"Listo para comprar") -> 0 | I10: =SUMIFS(Data_Ventas!$N:$N,Data_Ventas!$A:$A,">="&$A10,Data_Ventas!$A:$A,"<="&EOMONTH($A10,0),Data_Ventas!$H:$H,"Venta") -> 0 | J10: =COUNTIFS(Data_Ventas!$A:$A,">="&$A10,Data_Ventas!$A:$A,"<="&EOMONTH($A10,0),Data_Ventas!$H:$H,"Venta") -> 0 | K10: =SUMIFS(Data_Ventas!$R:$R,Data_Ventas!$A:$A,">="&$A10,Data_Ventas!$A:$A,"<="&EOMONTH($A10,0),Data_Ventas!$H:$H,"Venta") -> 0 | L10: =IF(OR(H10="",I10="",I10=0),"",MAX(1-ABS(H10-I10)/I10)) | M10: =IF(H10="","",H10-B10) -> -400000 | N10: =ROUNDUP(O10/Configuracion!$B$11,0) -> 325 | O10: =ROUNDUP(P10/Configuracion!$B$12,0) -> 65 | P10: =ROUNDUP(Q10/Configuracion!$B$13,0) -> 39 | Q10: =ROUNDUP(C10/Configuracion!$B$14,0) -> 13
A11: 46204 | B11: 400000 | C11: 10 | D11: 175000 | E11: 65000 | F11: 43000 | G11: 4 | H11: =SUMIFS(Data_Ventas!$N:$N,Data_Ventas!$A:$A,">="&$A11,Data_Ventas!$A:$A,"<="&EOMONTH($A11,0),Data_Ventas!$H:$H,"Separado")+I11+SUMIFS(Data_Cotiz!$N:$N,Data_Cotiz!$A:$A,">="&$A11,Data_Cotiz!$A:$A,"<="&EOMONTH($A11,0),Data_Cotiz!$H:$H,"Listo para comprar") -> 42000 | I11: =SUMIFS(Data_Ventas!$N:$N,Data_Ventas!$A:$A,">="&$A11,Data_Ventas!$A:$A,"<="&EOMONTH($A11,0),Data_Ventas!$H:$H,"Venta") -> 42000 | J11: =COUNTIFS(Data_Ventas!$A:$A,">="&$A11,Data_Ventas!$A:$A,"<="&EOMONTH($A11,0),Data_Ventas!$H:$H,"Venta") -> 1 | K11: =SUMIFS(Data_Ventas!$R:$R,Data_Ventas!$A:$A,">="&$A11,Data_Ventas!$A:$A,"<="&EOMONTH($A11,0),Data_Ventas!$H:$H,"Venta") -> 30000 | L11: =IF(OR(H11="",I11="",I11=0),"",MAX(1-ABS(H11-I11)/I11)) -> 1 | M11: =IF(H11="","",H11-B11) -> -358000 | N11: =ROUNDUP(O11/Configuracion!$B$11,0) -> 325 | O11: =ROUNDUP(P11/Configuracion!$B$12,0) -> 65 | P11: =ROUNDUP(Q11/Configuracion!$B$13,0) -> 39 | Q11: =ROUNDUP(C11/Configuracion!$B$14,0) -> 13
A12: 46235 | B12: 400000 | C12: 10 | D12: 175000 | E12: 65000 | F12: 43000 | G12: 4 | H12: =SUMIFS(Data_Ventas!$N:$N,Data_Ventas!$A:$A,">="&$A12,Data_Ventas!$A:$A,"<="&EOMONTH($A12,0),Data_Ventas!$H:$H,"Separado")+I12+SUMIFS(Data_Cotiz!$N:$N,Data_Cotiz!$A:$A,">="&$A12,Data_Cotiz!$A:$A,"<="&EOMONTH($A12,0),Data_Cotiz!$H:$H,"Listo para comprar") -> 125000 | I12: =SUMIFS(Data_Ventas!$N:$N,Data_Ventas!$A:$A,">="&$A12,Data_Ventas!$A:$A,"<="&EOMONTH($A12,0),Data_Ventas!$H:$H,"Venta") -> 125000 | J12: =COUNTIFS(Data_Ventas!$A:$A,">="&$A12,Data_Ventas!$A:$A,"<="&EOMONTH($A12,0),Data_Ventas!$H:$H,"Venta") -> 3 | K12: =SUMIFS(Data_Ventas!$R:$R,Data_Ventas!$A:$A,">="&$A12,Data_Ventas!$A:$A,"<="&EOMONTH($A12,0),Data_Ventas!$H:$H,"Venta") -> 8250 | L12: =IF(OR(H12="",I12="",I12=0),"",MAX(1-ABS(H12-I12)/I12)) -> 1 | M12: =IF(H12="","",H12-B12) -> -275000 | N12: =ROUNDUP(O12/Configuracion!$B$11,0) -> 325 | O12: =ROUNDUP(P12/Configuracion!$B$12,0) -> 65 | P12: =ROUNDUP(Q12/Configuracion!$B$13,0) -> 39 | Q12: =ROUNDUP(C12/Configuracion!$B$14,0) -> 13
A13: 46266 | B13: 400000 | C13: 10 | D13: 175000 | E13: 65000 | F13: 43000 | G13: 4 | H13: =SUMIFS(Data_Ventas!$N:$N,Data_Ventas!$A:$A,">="&$A13,Data_Ventas!$A:$A,"<="&EOMONTH($A13,0),Data_Ventas!$H:$H,"Separado")+I13+SUMIFS(Data_Cotiz!$N:$N,Data_Cotiz!$A:$A,">="&$A13,Data_Cotiz!$A:$A,"<="&EOMONTH($A13,0),Data_Cotiz!$H:$H,"Listo para comprar") -> 40000 | I13: =SUMIFS(Data_Ventas!$N:$N,Data_Ventas!$A:$A,">="&$A13,Data_Ventas!$A:$A,"<="&EOMONTH($A13,0),Data_Ventas!$H:$H,"Venta") -> 40000 | J13: =COUNTIFS(Data_Ventas!$A:$A,">="&$A13,Data_Ventas!$A:$A,"<="&EOMONTH($A13,0),Data_Ventas!$H:$H,"Venta") -> 1 | K13: =SUMIFS(Data_Ventas!$R:$R,Data_Ventas!$A:$A,">="&$A13,Data_Ventas!$A:$A,"<="&EOMONTH($A13,0),Data_Ventas!$H:$H,"Venta") -> 5000 | L13: =IF(OR(H13="",I13="",I13=0),"",MAX(1-ABS(H13-I13)/I13)) -> 1 | M13: =IF(H13="","",H13-B13) -> -360000 | N13: =ROUNDUP(O13/Configuracion!$B$11,0) -> 325 | O13: =ROUNDUP(P13/Configuracion!$B$12,0) -> 65 | P13: =ROUNDUP(Q13/Configuracion!$B$13,0) -> 39 | Q13: =ROUNDUP(C13/Configuracion!$B$14,0) -> 13
A14: 46296 | B14: 400000 | C14: 10 | D14: 175000 | E14: 65000 | F14: 43000 | G14: 4 | H14: =SUMIFS(Data_Ventas!$N:$N,Data_Ventas!$A:$A,">="&$A14,Data_Ventas!$A:$A,"<="&EOMONTH($A14,0),Data_Ventas!$H:$H,"Separado")+I14+SUMIFS(Data_Cotiz!$N:$N,Data_Cotiz!$A:$A,">="&$A14,Data_Cotiz!$A:$A,"<="&EOMONTH($A14,0),Data_Cotiz!$H:$H,"Listo para comprar") -> 0 | I14: =SUMIFS(Data_Ventas!$N:$N,Data_Ventas!$A:$A,">="&$A14,Data_Ventas!$A:$A,"<="&EOMONTH($A14,0),Data_Ventas!$H:$H,"Venta") -> 0 | J14: =COUNTIFS(Data_Ventas!$A:$A,">="&$A14,Data_Ventas!$A:$A,"<="&EOMONTH($A14,0),Data_Ventas!$H:$H,"Venta") -> 0 | K14: =SUMIFS(Data_Ventas!$R:$R,Data_Ventas!$A:$A,">="&$A14,Data_Ventas!$A:$A,"<="&EOMONTH($A14,0),Data_Ventas!$H:$H,"Venta") -> 0 | M14: =IF(H14="","",H14-B14) -> -400000 | N14: =ROUNDUP(O14/Configuracion!$B$11,0) -> 325 | O14: =ROUNDUP(P14/Configuracion!$B$12,0) -> 65 | P14: =ROUNDUP(Q14/Configuracion!$B$13,0) -> 39 | Q14: =ROUNDUP(C14/Configuracion!$B$14,0) -> 13
A15: 46327 | B15: 400000 | C15: 10 | D15: 175000 | E15: 65000 | F15: 43000 | G15: 4 | H15: =SUMIFS(Data_Ventas!$N:$N,Data_Ventas!$A:$A,">="&$A15,Data_Ventas!$A:$A,"<="&EOMONTH($A15,0),Data_Ventas!$H:$H,"Separado")+I15+SUMIFS(Data_Cotiz!$N:$N,Data_Cotiz!$A:$A,">="&$A15,Data_Cotiz!$A:$A,"<="&EOMONTH($A15,0),Data_Cotiz!$H:$H,"Listo para comprar") -> 0 | I15: =SUMIFS(Data_Ventas!$N:$N,Data_Ventas!$A:$A,">="&$A15,Data_Ventas!$A:$A,"<="&EOMONTH($A15,0),Data_Ventas!$H:$H,"Venta") -> 0 | J15: =COUNTIFS(Data_Ventas!$A:$A,">="&$A15,Data_Ventas!$A:$A,"<="&EOMONTH($A15,0),Data_Ventas!$H:$H,"Venta") -> 0 | K15: =SUMIFS(Data_Ventas!$R:$R,Data_Ventas!$A:$A,">="&$A15,Data_Ventas!$A:$A,"<="&EOMONTH($A15,0),Data_Ventas!$H:$H,"Venta") -> 0 | M15: =IF(H15="","",H15-B15) -> -400000 | N15: =ROUNDUP(O15/Configuracion!$B$11,0) -> 325 | O15: =ROUNDUP(P15/Configuracion!$B$12,0) -> 65 | P15: =ROUNDUP(Q15/Configuracion!$B$13,0) -> 39 | Q15: =ROUNDUP(C15/Configuracion!$B$14,0) -> 13
A16: 46357 | B16: 400000 | C16: 10 | D16: 175000 | E16: 65000 | F16: 43000 | G16: 4 | H16: =SUMIFS(Data_Ventas!$N:$N,Data_Ventas!$A:$A,">="&$A16,Data_Ventas!$A:$A,"<="&EOMONTH($A16,0),Data_Ventas!$H:$H,"Separado")+I16+SUMIFS(Data_Cotiz!$N:$N,Data_Cotiz!$A:$A,">="&$A16,Data_Cotiz!$A:$A,"<="&EOMONTH($A16,0),Data_Cotiz!$H:$H,"Listo para comprar") -> 0 | I16: =SUMIFS(Data_Ventas!$N:$N,Data_Ventas!$A:$A,">="&$A16,Data_Ventas!$A:$A,"<="&EOMONTH($A16,0),Data_Ventas!$H:$H,"Venta") -> 0 | J16: =COUNTIFS(Data_Ventas!$A:$A,">="&$A16,Data_Ventas!$A:$A,"<="&EOMONTH($A16,0),Data_Ventas!$H:$H,"Venta") -> 0 | K16: =SUMIFS(Data_Ventas!$R:$R,Data_Ventas!$A:$A,">="&$A16,Data_Ventas!$A:$A,"<="&EOMONTH($A16,0),Data_Ventas!$H:$H,"Venta") -> 0 | M16: =IF(H16="","",H16-B16) -> -400000 | N16: =ROUNDUP(O16/Configuracion!$B$11,0) -> 325 | O16: =ROUNDUP(P16/Configuracion!$B$12,0) -> 65 | P16: =ROUNDUP(Q16/Configuracion!$B$13,0) -> 39 | Q16: =ROUNDUP(C16/Configuracion!$B$14,0) -> 13

Sheet Resum_Semanal
A1: RESUMEN SEMANAL AUTOMÁTICO
B3: PROYECTADA | G3: REAL
A4: Semana inicia | B4: Leads | C4: Visitas | D4: Separaciones | E4: Ventas | F4: Facturación | G4: Leads | H4: Visitas | I4: Separaciones | J4: Ventas | K4: Facturación | L4: Cumplimiento S/.
A5: =Dashboard!$E$5-WEEKDAY(Dashboard!$E$5,2)+1-78 -> 46215 | B5: =IFERROR(LET(meta,SUMIFS(Meta!$N$5:$N$16,Meta!$A$5:$A$16,">="&EOMONTH($A5,-1)+1,Meta!$A$5:$A$16,"<="&EOMONTH($A5,0)),semanas,COUNTIFS($A$5:$A$35,">="&EOMONTH($A5,-1)+1,$A$5:$A$35,"<="&EOMONTH($A5,0)),posicion,COUNTIFS($A$5:$A5,">="&EOMONTH($A5,-1)+1,$A$5:$A5,"<="&EOMONTH($A5,0)),QUOTIENT(meta,semanas)+IF(posicion<=MOD(meta,semanas),1,0)),"") -> 109 | C5: =IFERROR(LET(meta,SUMIFS(Meta!$P$5:$P$16,Meta!$A$5:$A$16,">="&EOMONTH($A5,-1)+1,Meta!$A$5:$A$16,"<="&EOMONTH($A5,0)),semanas,COUNTIFS($A$5:$A$35,">="&EOMONTH($A5,-1)+1,$A$5:$A$35,"<="&EOMONTH($A5,0)),posicion,COUNTIFS($A$5:$A5,">="&EOMONTH($A5,-1)+1,$A$5:$A5,"<="&EOMONTH($A5,0)),QUOTIENT(meta,semanas)+IF(posicion<=MOD(meta,semanas),1,0)),"") -> 13 | D5: =IFERROR(LET(meta,SUMIFS(Meta!$Q$5:$Q$16,Meta!$A$5:$A$16,">="&EOMONTH($A5,-1)+1,Meta!$A$5:$A$16,"<="&EOMONTH($A5,0)),semanas,COUNTIFS($A$5:$A$35,">="&EOMONTH($A5,-1)+1,$A$5:$A$35,"<="&EOMONTH($A5,0)),posicion,COUNTIFS($A$5:$A5,">="&EOMONTH($A5,-1)+1,$A$5:$A5,"<="&EOMONTH($A5,0)),QUOTIENT(meta,semanas)+IF(posicion<=MOD(meta,semanas),1,0)),"") -> 5 | E5: =IFERROR(LET(meta,SUMIFS(Meta!$C$5:$C$16,Meta!$A$5:$A$16,">="&EOMONTH($A5,-1)+1,Meta!$A$5:$A$16,"<="&EOMONTH($A5,0)),semanas,COUNTIFS($A$5:$A$35,">="&EOMONTH($A5,-1)+1,$A$5:$A$35,"<="&EOMONTH($A5,0)),posicion,COUNTIFS($A$5:$A5,">="&EOMONTH($A5,-1)+1,$A$5:$A5,"<="&EOMONTH($A5,0)),QUOTIENT(meta,semanas)+IF(posicion<=MOD(meta,semanas),1,0)),"") -> 4 | F5: =IFERROR(SUMIFS(Meta!$B$5:$B$16,Meta!$A$5:$A$16,">="&EOMONTH($A5,-1)+1,Meta!$A$5:$A$16,"<="&EOMONTH($A5,0))/COUNTIFS($A$5:$A$35,">="&EOMONTH($A5,-1)+1,$A$5:$A$35,"<="&EOMONTH($A5,0)),"") -> 133333.33 | G5: =COUNTIFS(Data_Ventas!$E$2:$E1001,">="&A5,Data_Ventas!$E$2:$E1001,"<="&A5+6) -> 0 | H5: =COUNTIFS(Data_Ventas!$A$2:$A1001,">="&A5,Data_Ventas!$A$2:$A1001,"<="&A5+6,Data_Ventas!$H$2:$H1001,"Visitó proyecto") -> 0 | I5: =COUNTIFS(Data_Ventas!$A$2:$A1001,">="&A5,Data_Ventas!$A$2:$A1001,"<="&A5+6,Data_Ventas!$H$2:$H1001,"Separado") -> 0 | J5: =COUNTIFS(Data_Ventas!$A$2:$A1001,">="&A5,Data_Ventas!$A$2:$A1001,"<="&A5+6,Data_Ventas!$H$2:$H1001,"Venta") -> 0 | K5: =SUMIFS(Data_Ventas!$N$2:$N1001,Data_Ventas!$A$2:$A1001,">="&A5,Data_Ventas!$A$2:$A1001,"<="&A5+6,Data_Ventas!$H$2:$H1001,"Venta") -> 0 | L5: =IFERROR(K5/F5,"0%") -> 0
A6: =A5+7 -> 46222 | B6: =IFERROR(LET(meta,SUMIFS(Meta!$N$5:$N$16,Meta!$A$5:$A$16,">="&EOMONTH($A6,-1)+1,Meta!$A$5:$A$16,"<="&EOMONTH($A6,0)),semanas,COUNTIFS($A$5:$A$35,">="&EOMONTH($A6,-1)+1,$A$5:$A$35,"<="&EOMONTH($A6,0)),posicion,COUNTIFS($A$5:$A6,">="&EOMONTH($A6,-1)+1,$A$5:$A6,"<="&EOMONTH($A6,0)),QUOTIENT(meta,semanas)+IF(posicion<=MOD(meta,semanas),1,0)),"") -> 108 | C6: =IFERROR(LET(meta,SUMIFS(Meta!$P$5:$P$16,Meta!$A$5:$A$16,">="&EOMONTH($A6,-1)+1,Meta!$A$5:$A$16,"<="&EOMONTH($A6,0)),semanas,COUNTIFS($A$5:$A$35,">="&EOMONTH($A6,-1)+1,$A$5:$A$35,"<="&EOMONTH($A6,0)),posicion,COUNTIFS($A$5:$A6,">="&EOMONTH($A6,-1)+1,$A$5:$A6,"<="&EOMONTH($A6,0)),QUOTIENT(meta,semanas)+IF(posicion<=MOD(meta,semanas),1,0)),"") -> 13 | D6: =IFERROR(LET(meta,SUMIFS(Meta!$Q$5:$Q$16,Meta!$A$5:$A$16,">="&EOMONTH($A6,-1)+1,Meta!$A$5:$A$16,"<="&EOMONTH($A6,0)),semanas,COUNTIFS($A$5:$A$35,">="&EOMONTH($A6,-1)+1,$A$5:$A$35,"<="&EOMONTH($A6,0)),posicion,COUNTIFS($A$5:$A6,">="&EOMONTH($A6,-1)+1,$A$5:$A6,"<="&EOMONTH($A6,0)),QUOTIENT(meta,semanas)+IF(posicion<=MOD(meta,semanas),1,0)),"") -> 4 | E6: =IFERROR(LET(meta,SUMIFS(Meta!$C$5:$C$16,Meta!$A$5:$A$16,">="&EOMONTH($A6,-1)+1,Meta!$A$5:$A$16,"<="&EOMONTH($A6,0)),semanas,COUNTIFS($A$5:$A$35,">="&EOMONTH($A6,-1)+1,$A$5:$A$35,"<="&EOMONTH($A6,0)),posicion,COUNTIFS($A$5:$A6,">="&EOMONTH($A6,-1)+1,$A$5:$A6,"<="&EOMONTH($A6,0)),QUOTIENT(meta,semanas)+IF(posicion<=MOD(meta,semanas),1,0)),"") -> 3 | F6: =IFERROR(SUMIFS(Meta!$B$5:$B$16,Meta!$A$5:$A$16,">="&EOMONTH($A6,-1)+1,Meta!$A$5:$A$16,"<="&EOMONTH($A6,0))/COUNTIFS($A$5:$A$35,">="&EOMONTH($A6,-1)+1,$A$5:$A$35,"<="&EOMONTH($A6,0)),"") -> 133333.33 | G6: =COUNTIFS(Data_Ventas!$E$2:$E1001,">="&A6,Data_Ventas!$E$2:$E1001,"<="&A6+6) -> 0 | H6: =COUNTIFS(Data_Ventas!$A$2:$A1001,">="&A6,Data_Ventas!$A$2:$A1001,"<="&A6+6,Data_Ventas!$H$2:$H1001,"Visitó proyecto") -> 0 | I6: =COUNTIFS(Data_Ventas!$A$2:$A1001,">="&A6,Data_Ventas!$A$2:$A1001,"<="&A6+6,Data_Ventas!$H$2:$H1001,"Separado") -> 0 | J6: =COUNTIFS(Data_Ventas!$A$2:$A1001,">="&A6,Data_Ventas!$A$2:$A1001,"<="&A6+6,Data_Ventas!$H$2:$H1001,"Venta") -> 0 | K6: =SUMIFS(Data_Ventas!$N$2:$N1001,Data_Ventas!$A$2:$A1001,">="&A6,Data_Ventas!$A$2:$A1001,"<="&A6+6,Data_Ventas!$H$2:$H1001,"Venta") -> 0 | L6: =IFERROR(K6/F6,"0%") -> 0
A7: =A6+7 -> 46229 | B7: =IFERROR(LET(meta,SUMIFS(Meta!$N$5:$N$16,Meta!$A$5:$A$16,">="&EOMONTH($A7,-1)+1,Meta!$A$5:$A$16,"<="&EOMONTH($A7,0)),semanas,COUNTIFS($A$5:$A$35,">="&EOMONTH($A7,-1)+1,$A$5:$A$35,"<="&EOMONTH($A7,0)),posicion,COUNTIFS($A$5:$A7,">="&EOMONTH($A7,-1)+1,$A$5:$A7,"<="&EOMONTH($A7,0)),QUOTIENT(meta,semanas)+IF(posicion<=MOD(meta,semanas),1,0)),"") -> 108 | C7: =IFERROR(LET(meta,SUMIFS(Meta!$P$5:$P$16,Meta!$A$5:$A$16,">="&EOMONTH($A7,-1)+1,Meta!$A$5:$A$16,"<="&EOMONTH($A7,0)),semanas,COUNTIFS($A$5:$A$35,">="&EOMONTH($A7,-1)+1,$A$5:$A$35,"<="&EOMONTH($A7,0)),posicion,COUNTIFS($A$5:$A7,">="&EOMONTH($A7,-1)+1,$A$5:$A7,"<="&EOMONTH($A7,0)),QUOTIENT(meta,semanas)+IF(posicion<=MOD(meta,semanas),1,0)),"") -> 13 | D7: =IFERROR(LET(meta,SUMIFS(Meta!$Q$5:$Q$16,Meta!$A$5:$A$16,">="&EOMONTH($A7,-1)+1,Meta!$A$5:$A$16,"<="&EOMONTH($A7,0)),semanas,COUNTIFS($A$5:$A$35,">="&EOMONTH($A7,-1)+1,$A$5:$A$35,"<="&EOMONTH($A7,0)),posicion,COUNTIFS($A$5:$A7,">="&EOMONTH($A7,-1)+1,$A$5:$A7,"<="&EOMONTH($A7,0)),QUOTIENT(meta,semanas)+IF(posicion<=MOD(meta,semanas),1,0)),"") -> 4 | E7: =IFERROR(LET(meta,SUMIFS(Meta!$C$5:$C$16,Meta!$A$5:$A$16,">="&EOMONTH($A7,-1)+1,Meta!$A$5:$A$16,"<="&EOMONTH($A7,0)),semanas,COUNTIFS($A$5:$A$35,">="&EOMONTH($A7,-1)+1,$A$5:$A$35,"<="&EOMONTH($A7,0)),posicion,COUNTIFS($A$5:$A7,">="&EOMONTH($A7,-1)+1,$A$5:$A7,"<="&EOMONTH($A7,0)),QUOTIENT(meta,semanas)+IF(posicion<=MOD(meta,semanas),1,0)),"") -> 3 | F7: =IFERROR(SUMIFS(Meta!$B$5:$B$16,Meta!$A$5:$A$16,">="&EOMONTH($A7,-1)+1,Meta!$A$5:$A$16,"<="&EOMONTH($A7,0))/COUNTIFS($A$5:$A$35,">="&EOMONTH($A7,-1)+1,$A$5:$A$35,"<="&EOMONTH($A7,0)),"") -> 133333.33 | G7: =COUNTIFS(Data_Ventas!$E$2:$E1001,">="&A7,Data_Ventas!$E$2:$E1001,"<="&A7+6) -> 0 | H7: =COUNTIFS(Data_Ventas!$A$2:$A1001,">="&A7,Data_Ventas!$A$2:$A1001,"<="&A7+6,Data_Ventas!$H$2:$H1001,"Visitó proyecto") -> 0 | I7: =COUNTIFS(Data_Ventas!$A$2:$A1001,">="&A7,Data_Ventas!$A$2:$A1001,"<="&A7+6,Data_Ventas!$H$2:$H1001,"Separado") -> 0 | J7: =COUNTIFS(Data_Ventas!$A$2:$A1001,">="&A7,Data_Ventas!$A$2:$A1001,"<="&A7+6,Data_Ventas!$H$2:$H1001,"Venta") -> 0 | K7: =SUMIFS(Data_Ventas!$N$2:$N1001,Data_Ventas!$A$2:$A1001,">="&A7,Data_Ventas!$A$2:$A1001,"<="&A7+6,Data_Ventas!$H$2:$H1001,"Venta") -> 0 | L7: =IFERROR(K7/F7,"0%") -> 0
A8: =A7+7 -> 46236 | B8: =IFERROR(LET(meta,SUMIFS(Meta!$N$5:$N$16,Meta!$A$5:$A$16,">="&EOMONTH($A8,-1)+1,Meta!$A$5:$A$16,"<="&EOMONTH($A8,0)),semanas,COUNTIFS($A$5:$A$35,">="&EOMONTH($A8,-1)+1,$A$5:$A$35,"<="&EOMONTH($A8,0)),posicion,COUNTIFS($A$5:$A8,">="&EOMONTH($A8,-1)+1,$A$5:$A8,"<="&EOMONTH($A8,0)),QUOTIENT(meta,semanas)+IF(posicion<=MOD(meta,semanas),1,0)),"") -> 65 | C8: =IFERROR(LET(meta,SUMIFS(Meta!$P$5:$P$16,Meta!$A$5:$A$16,">="&EOMONTH($A8,-1)+1,Meta!$A$5:$A$16,"<="&EOMONTH($A8,0)),semanas,COUNTIFS($A$5:$A$35,">="&EOMONTH($A8,-1)+1,$A$5:$A$35,"<="&EOMONTH($A8,0)),posicion,COUNTIFS($A$5:$A8,">="&EOMONTH($A8,-1)+1,$A$5:$A8,"<="&EOMONTH($A8,0)),QUOTIENT(meta,semanas)+IF(posicion<=MOD(meta,semanas),1,0)),"") -> 8 | D8: =IFERROR(LET(meta,SUMIFS(Meta!$Q$5:$Q$16,Meta!$A$5:$A$16,">="&EOMONTH($A8,-1)+1,Meta!$A$5:$A$16,"<="&EOMONTH($A8,0)),semanas,COUNTIFS($A$5:$A$35,">="&EOMONTH($A8,-1)+1,$A$5:$A$35,"<="&EOMONTH($A8,0)),posicion,COUNTIFS($A$5:$A8,">="&EOMONTH($A8,-1)+1,$A$5:$A8,"<="&EOMONTH($A8,0)),QUOTIENT(meta,semanas)+IF(posicion<=MOD(meta,semanas),1,0)),"") -> 3 | E8: =IFERROR(LET(meta,SUMIFS(Meta!$C$5:$C$16,Meta!$A$5:$A$16,">="&EOMONTH($A8,-1)+1,Meta!$A$5:$A$16,"<="&EOMONTH($A8,0)),semanas,COUNTIFS($A$5:$A$35,">="&EOMONTH($A8,-1)+1,$A$5:$A$35,"<="&EOMONTH($A8,0)),posicion,COUNTIFS($A$5:$A8,">="&EOMONTH($A8,-1)+1,$A$5:$A8,"<="&EOMONTH($A8,0)),QUOTIENT(meta,semanas)+IF(posicion<=MOD(meta,semanas),1,0)),"") -> 2 | F8: =IFERROR(SUMIFS(Meta!$B$5:$B$16,Meta!$A$5:$A$16,">="&EOMONTH($A8,-1)+1,Meta!$A$5:$A$16,"<="&EOMONTH($A8,0))/COUNTIFS($A$5:$A$35,">="&EOMONTH($A8,-1)+1,$A$5:$A$35,"<="&EOMONTH($A8,0)),"") -> 80000 | G8: =COUNTIFS(Data_Ventas!$E$2:$E1001,">="&A8,Data_Ventas!$E$2:$E1001,"<="&A8+6) -> 0 | H8: =COUNTIFS(Data_Ventas!$A$2:$A1001,">="&A8,Data_Ventas!$A$2:$A1001,"<="&A8+6,Data_Ventas!$H$2:$H1001,"Visitó proyecto") -> 0 | I8: =COUNTIFS(Data_Ventas!$A$2:$A1001,">="&A8,Data_Ventas!$A$2:$A1001,"<="&A8+6,Data_Ventas!$H$2:$H1001,"Separado") -> 0 | J8: =COUNTIFS(Data_Ventas!$A$2:$A1001,">="&A8,Data_Ventas!$A$2:$A1001,"<="&A8+6,Data_Ventas!$H$2:$H1001,"Venta") -> 0 | K8: =SUMIFS(Data_Ventas!$N$2:$N1001,Data_Ventas!$A$2:$A1001,">="&A8,Data_Ventas!$A$2:$A1001,"<="&A8+6,Data_Ventas!$H$2:$H1001,"Venta") -> 0 | L8: =IFERROR(K8/F8,"0%") -> 0
A9: =A8+7 -> 46243 | B9: =IFERROR(LET(meta,SUMIFS(Meta!$N$5:$N$16,Meta!$A$5:$A$16,">="&EOMONTH($A9,-1)+1,Meta!$A$5:$A$16,"<="&EOMONTH($A9,0)),semanas,COUNTIFS($A$5:$A$35,">="&EOMONTH($A9,-1)+1,$A$5:$A$35,"<="&EOMONTH($A9,0)),posicion,COUNTIFS($A$5:$A9,">="&EOMONTH($A9,-1)+1,$A$5:$A9,"<="&EOMONTH($A9,0)),QUOTIENT(meta,semanas)+IF(posicion<=MOD(meta,semanas),1,0)),"") -> 65 | C9: =IFERROR(LET(meta,SUMIFS(Meta!$P$5:$P$16,Meta!$A$5:$A$16,">="&EOMONTH($A9,-1)+1,Meta!$A$5:$A$16,"<="&EOMONTH($A9,0)),semanas,COUNTIFS($A$5:$A$35,">="&EOMONTH($A9,-1)+1,$A$5:$A$35,"<="&EOMONTH($A9,0)),posicion,COUNTIFS($A$5:$A9,">="&EOMONTH($A9,-1)+1,$A$5:$A9,"<="&EOMONTH($A9,0)),QUOTIENT(meta,semanas)+IF(posicion<=MOD(meta,semanas),1,0)),"") -> 8 | D9: =IFERROR(LET(meta,SUMIFS(Meta!$Q$5:$Q$16,Meta!$A$5:$A$16,">="&EOMONTH($A9,-1)+1,Meta!$A$5:$A$16,"<="&EOMONTH($A9,0)),semanas,COUNTIFS($A$5:$A$35,">="&EOMONTH($A9,-1)+1,$A$5:$A$35,"<="&EOMONTH($A9,0)),posicion,COUNTIFS($A$5:$A9,">="&EOMONTH($A9,-1)+1,$A$5:$A9,"<="&EOMONTH($A9,0)),QUOTIENT(meta,semanas)+IF(posicion<=MOD(meta,semanas),1,0)),"") -> 3 | E9: =IFERROR(LET(meta,SUMIFS(Meta!$C$5:$C$16,Meta!$A$5:$A$16,">="&EOMONTH($A9,-1)+1,Meta!$A$5:$A$16,"<="&EOMONTH($A9,0)),semanas,COUNTIFS($A$5:$A$35,">="&EOMONTH($A9,-1)+1,$A$5:$A$35,"<="&EOMONTH($A9,0)),posicion,COUNTIFS($A$5:$A9,">="&EOMONTH($A9,-1)+1,$A$5:$A9,"<="&EOMONTH($A9,0)),QUOTIENT(meta,semanas)+IF(posicion<=MOD(meta,semanas),1,0)),"") -> 2 | F9: =IFERROR(SUMIFS(Meta!$B$5:$B$16,Meta!$A$5:$A$16,">="&EOMONTH($A9,-1)+1,Meta!$A$5:$A$16,"<="&EOMONTH($A9,0))/COUNTIFS($A$5:$A$35,">="&EOMONTH($A9,-1)+1,$A$5:$A$35,"<="&EOMONTH($A9,0)),"") -> 80000 | G9: =COUNTIFS(Data_Ventas!$E$2:$E1001,">="&A9,Data_Ventas!$E$2:$E1001,"<="&A9+6) -> 0 | H9: =COUNTIFS(Data_Ventas!$A$2:$A1001,">="&A9,Data_Ventas!$A$2:$A1001,"<="&A9+6,Data_Ventas!$H$2:$H1001,"Visitó proyecto") -> 0 | I9: =COUNTIFS(Data_Ventas!$A$2:$A1001,">="&A9,Data_Ventas!$A$2:$A1001,"<="&A9+6,Data_Ventas!$H$2:$H1001,"Separado") -> 0 | J9: =COUNTIFS(Data_Ventas!$A$2:$A1001,">="&A9,Data_Ventas!$A$2:$A1001,"<="&A9+6,Data_Ventas!$H$2:$H1001,"Venta") -> 0 | K9: =SUMIFS(Data_Ventas!$N$2:$N1001,Data_Ventas!$A$2:$A1001,">="&A9,Data_Ventas!$A$2:$A1001,"<="&A9+6,Data_Ventas!$H$2:$H1001,"Venta") -> 0 | L9: =IFERROR(K9/F9,"0%") -> 0
A10: =A9+7 -> 46250 | B10: =IFERROR(LET(meta,SUMIFS(Meta!$N$5:$N$16,Meta!$A$5:$A$16,">="&EOMONTH($A10,-1)+1,Meta!$A$5:$A$16,"<="&EOMONTH($A10,0)),semanas,COUNTIFS($A$5:$A$35,">="&EOMONTH($A10,-1)+1,$A$5:$A$35,"<="&EOMONTH($A10,0)),posicion,COUNTIFS($A$5:$A10,">="&EOMONTH($A10,-1)+1,$A$5:$A10,"<="&EOMONTH($A10,0)),QUOTIENT(meta,semanas)+IF(posicion<=MOD(meta,semanas),1,0)),"") -> 65 | C10: =IFERROR(LET(meta,SUMIFS(Meta!$P$5:$P$16,Meta!$A$5:$A$16,">="&EOMONTH($A10,-1)+1,Meta!$A$5:$A$16,"<="&EOMONTH($A10,0)),semanas,COUNTIFS($A$5:$A$35,">="&EOMONTH($A10,-1)+1,$A$5:$A$35,"<="&EOMONTH($A10,0)),posicion,COUNTIFS($A$5:$A10,">="&EOMONTH($A10,-1)+1,$A$5:$A10,"<="&EOMONTH($A10,0)),QUOTIENT(meta,semanas)+IF(posicion<=MOD(meta,semanas),1,0)),"") -> 8 | D10: =IFERROR(LET(meta,SUMIFS(Meta!$Q$5:$Q$16,Meta!$A$5:$A$16,">="&EOMONTH($A10,-1)+1,Meta!$A$5:$A$16,"<="&EOMONTH($A10,0)),semanas,COUNTIFS($A$5:$A$35,">="&EOMONTH($A10,-1)+1,$A$5:$A$35,"<="&EOMONTH($A10,0)),posicion,COUNTIFS($A$5:$A10,">="&EOMONTH($A10,-1)+1,$A$5:$A10,"<="&EOMONTH($A10,0)),QUOTIENT(meta,semanas)+IF(posicion<=MOD(meta,semanas),1,0)),"") -> 3 | E10: =IFERROR(LET(meta,SUMIFS(Meta!$C$5:$C$16,Meta!$A$5:$A$16,">="&EOMONTH($A10,-1)+1,Meta!$A$5:$A$16,"<="&EOMONTH($A10,0)),semanas,COUNTIFS($A$5:$A$35,">="&EOMONTH($A10,-1)+1,$A$5:$A$35,"<="&EOMONTH($A10,0)),posicion,COUNTIFS($A$5:$A10,">="&EOMONTH($A10,-1)+1,$A$5:$A10,"<="&EOMONTH($A10,0)),QUOTIENT(meta,semanas)+IF(posicion<=MOD(meta,semanas),1,0)),"") -> 2 | F10: =IFERROR(SUMIFS(Meta!$B$5:$B$16,Meta!$A$5:$A$16,">="&EOMONTH($A10,-1)+1,Meta!$A$5:$A$16,"<="&EOMONTH($A10,0))/COUNTIFS($A$5:$A$35,">="&EOMONTH($A10,-1)+1,$A$5:$A$35,"<="&EOMONTH($A10,0)),"") -> 80000 | G10: =COUNTIFS(Data_Ventas!$E$2:$E1001,">="&A10,Data_Ventas!$E$2:$E1001,"<="&A10+6) -> 0 | H10: =COUNTIFS(Data_Ventas!$A$2:$A1001,">="&A10,Data_Ventas!$A$2:$A1001,"<="&A10+6,Data_Ventas!$H$2:$H1001,"Visitó proyecto") -> 0 | I10: =COUNTIFS(Data_Ventas!$A$2:$A1001,">="&A10,Data_Ventas!$A$2:$A1001,"<="&A10+6,Data_Ventas!$H$2:$H1001,"Separado") -> 0 | J10: =COUNTIFS(Data_Ventas!$A$2:$A1001,">="&A10,Data_Ventas!$A$2:$A1001,"<="&A10+6,Data_Ventas!$H$2:$H1001,"Venta") -> 1 | K10: =SUMIFS(Data_Ventas!$N$2:$N1001,Data_Ventas!$A$2:$A1001,">="&A10,Data_Ventas!$A$2:$A1001,"<="&A10+6,Data_Ventas!$H$2:$H1001,"Venta") -> 55000 | L10: =IFERROR(K10/F10,"0%") -> 0.6875
A11: =A10+7 -> 46257 | B11: =IFERROR(LET(meta,SUMIFS(Meta!$N$5:$N$16,Meta!$A$5:$A$16,">="&EOMONTH($A11,-1)+1,Meta!$A$5:$A$16,"<="&EOMONTH($A11,0)),semanas,COUNTIFS($A$5:$A$35,">="&EOMONTH($A11,-1)+1,$A$5:$A$35,"<="&EOMONTH($A11,0)),posicion,COUNTIFS($A$5:$A11,">="&EOMONTH($A11,-1)+1,$A$5:$A11,"<="&EOMONTH($A11,0)),QUOTIENT(meta,semanas)+IF(posicion<=MOD(meta,semanas),1,0)),"") -> 65 | C11: =IFERROR(LET(meta,SUMIFS(Meta!$P$5:$P$16,Meta!$A$5:$A$16,">="&EOMONTH($A11,-1)+1,Meta!$A$5:$A$16,"<="&EOMONTH($A11,0)),semanas,COUNTIFS($A$5:$A$35,">="&EOMONTH($A11,-1)+1,$A$5:$A$35,"<="&EOMONTH($A11,0)),posicion,COUNTIFS($A$5:$A11,">="&EOMONTH($A11,-1)+1,$A$5:$A11,"<="&EOMONTH($A11,0)),QUOTIENT(meta,semanas)+IF(posicion<=MOD(meta,semanas),1,0)),"") -> 8 | D11: =IFERROR(LET(meta,SUMIFS(Meta!$Q$5:$Q$16,Meta!$A$5:$A$16,">="&EOMONTH($A11,-1)+1,Meta!$A$5:$A$16,"<="&EOMONTH($A11,0)),semanas,COUNTIFS($A$5:$A$35,">="&EOMONTH($A11,-1)+1,$A$5:$A$35,"<="&EOMONTH($A11,0)),posicion,COUNTIFS($A$5:$A11,">="&EOMONTH($A11,-1)+1,$A$5:$A11,"<="&EOMONTH($A11,0)),QUOTIENT(meta,semanas)+IF(posicion<=MOD(meta,semanas),1,0)),"") -> 2 | E11: =IFERROR(LET(meta,SUMIFS(Meta!$C$5:$C$16,Meta!$A$5:$A$16,">="&EOMONTH($A11,-1)+1,Meta!$A$5:$A$16,"<="&EOMONTH($A11,0)),semanas,COUNTIFS($A$5:$A$35,">="&EOMONTH($A11,-1)+1,$A$5:$A$35,"<="&EOMONTH($A11,0)),posicion,COUNTIFS($A$5:$A11,">="&EOMONTH($A11,-1)+1,$A$5:$A11,"<="&EOMONTH($A11,0)),QUOTIENT(meta,semanas)+IF(posicion<=MOD(meta,semanas),1,0)),"") -> 2 | F11: =IFERROR(SUMIFS(Meta!$B$5:$B$16,Meta!$A$5:$A$16,">="&EOMONTH($A11,-1)+1,Meta!$A$5:$A$16,"<="&EOMONTH($A11,0))/COUNTIFS($A$5:$A$35,">="&EOMONTH($A11,-1)+1,$A$5:$A$35,"<="&EOMONTH($A11,0)),"") -> 80000 | G11: =COUNTIFS(Data_Ventas!$E$2:$E1001,">="&A11,Data_Ventas!$E$2:$E1001,"<="&A11+6) -> 0 | H11: =COUNTIFS(Data_Ventas!$A$2:$A1001,">="&A11,Data_Ventas!$A$2:$A1001,"<="&A11+6,Data_Ventas!$H$2:$H1001,"Visitó proyecto") -> 0 | I11: =COUNTIFS(Data_Ventas!$A$2:$A1001,">="&A11,Data_Ventas!$A$2:$A1001,"<="&A11+6,Data_Ventas!$H$2:$H1001,"Separado") -> 0 | J11: =COUNTIFS(Data_Ventas!$A$2:$A1001,">="&A11,Data_Ventas!$A$2:$A1001,"<="&A11+6,Data_Ventas!$H$2:$H1001,"Venta") -> 0 | K11: =SUMIFS(Data_Ventas!$N$2:$N1001,Data_Ventas!$A$2:$A1001,">="&A11,Data_Ventas!$A$2:$A1001,"<="&A11+6,Data_Ventas!$H$2:$H1001,"Venta") -> 0 | L11: =IFERROR(K11/F11,"0%") -> 0
A12: =A11+7 -> 46264 | B12: =IFERROR(LET(meta,SUMIFS(Meta!$N$5:$N$16,Meta!$A$5:$A$16,">="&EOMONTH($A12,-1)+1,Meta!$A$5:$A$16,"<="&EOMONTH($A12,0)),semanas,COUNTIFS($A$5:$A$35,">="&EOMONTH($A12,-1)+1,$A$5:$A$35,"<="&EOMONTH($A12,0)),posicion,COUNTIFS($A$5:$A12,">="&EOMONTH($A12,-1)+1,$A$5:$A12,"<="&EOMONTH($A12,0)),QUOTIENT(meta,semanas)+IF(posicion<=MOD(meta,semanas),1,0)),"") -> 65 | C12: =IFERROR(LET(meta,SUMIFS(Meta!$P$5:$P$16,Meta!$A$5:$A$16,">="&EOMONTH($A12,-1)+1,Meta!$A$5:$A$16,"<="&EOMONTH($A12,0)),semanas,COUNTIFS($A$5:$A$35,">="&EOMONTH($A12,-1)+1,$A$5:$A$35,"<="&EOMONTH($A12,0)),posicion,COUNTIFS($A$5:$A12,">="&EOMONTH($A12,-1)+1,$A$5:$A12,"<="&EOMONTH($A12,0)),QUOTIENT(meta,semanas)+IF(posicion<=MOD(meta,semanas),1,0)),"") -> 7 | D12: =IFERROR(LET(meta,SUMIFS(Meta!$Q$5:$Q$16,Meta!$A$5:$A$16,">="&EOMONTH($A12,-1)+1,Meta!$A$5:$A$16,"<="&EOMONTH($A12,0)),semanas,COUNTIFS($A$5:$A$35,">="&EOMONTH($A12,-1)+1,$A$5:$A$35,"<="&EOMONTH($A12,0)),posicion,COUNTIFS($A$5:$A12,">="&EOMONTH($A12,-1)+1,$A$5:$A12,"<="&EOMONTH($A12,0)),QUOTIENT(meta,semanas)+IF(posicion<=MOD(meta,semanas),1,0)),"") -> 2 | E12: =IFERROR(LET(meta,SUMIFS(Meta!$C$5:$C$16,Meta!$A$5:$A$16,">="&EOMONTH($A12,-1)+1,Meta!$A$5:$A$16,"<="&EOMONTH($A12,0)),semanas,COUNTIFS($A$5:$A$35,">="&EOMONTH($A12,-1)+1,$A$5:$A$35,"<="&EOMONTH($A12,0)),posicion,COUNTIFS($A$5:$A12,">="&EOMONTH($A12,-1)+1,$A$5:$A12,"<="&EOMONTH($A12,0)),QUOTIENT(meta,semanas)+IF(posicion<=MOD(meta,semanas),1,0)),"") -> 2 | F12: =IFERROR(SUMIFS(Meta!$B$5:$B$16,Meta!$A$5:$A$16,">="&EOMONTH($A12,-1)+1,Meta!$A$5:$A$16,"<="&EOMONTH($A12,0))/COUNTIFS($A$5:$A$35,">="&EOMONTH($A12,-1)+1,$A$5:$A$35,"<="&EOMONTH($A12,0)),"") -> 80000 | G12: =COUNTIFS(Data_Ventas!$E$2:$E1001,">="&A12,Data_Ventas!$E$2:$E1001,"<="&A12+6) -> 0 | H12: =COUNTIFS(Data_Ventas!$A$2:$A1001,">="&A12,Data_Ventas!$A$2:$A1001,"<="&A12+6,Data_Ventas!$H$2:$H1001,"Visitó proyecto") -> 0 | I12: =COUNTIFS(Data_Ventas!$A$2:$A1001,">="&A12,Data_Ventas!$A$2:$A1001,"<="&A12+6,Data_Ventas!$H$2:$H1001,"Separado") -> 0 | J12: =COUNTIFS(Data_Ventas!$A$2:$A1001,">="&A12,Data_Ventas!$A$2:$A1001,"<="&A12+6,Data_Ventas!$H$2:$H1001,"Venta") -> 2 | K12: =SUMIFS(Data_Ventas!$N$2:$N1001,Data_Ventas!$A$2:$A1001,">="&A12,Data_Ventas!$A$2:$A1001,"<="&A12+6,Data_Ventas!$H$2:$H1001,"Venta") -> 70000 | L12: =IFERROR(K12/F12,"0%") -> 0.875
A13: =A12+7 -> 46271 | B13: =IFERROR(LET(meta,SUMIFS(Meta!$N$5:$N$16,Meta!$A$5:$A$16,">="&EOMONTH($A13,-1)+1,Meta!$A$5:$A$16,"<="&EOMONTH($A13,0)),semanas,COUNTIFS($A$5:$A$35,">="&EOMONTH($A13,-1)+1,$A$5:$A$35,"<="&EOMONTH($A13,0)),posicion,COUNTIFS($A$5:$A13,">="&EOMONTH($A13,-1)+1,$A$5:$A13,"<="&EOMONTH($A13,0)),QUOTIENT(meta,semanas)+IF(posicion<=MOD(meta,semanas),1,0)),"") -> 82 | C13: =IFERROR(LET(meta,SUMIFS(Meta!$P$5:$P$16,Meta!$A$5:$A$16,">="&EOMONTH($A13,-1)+1,Meta!$A$5:$A$16,"<="&EOMONTH($A13,0)),semanas,COUNTIFS($A$5:$A$35,">="&EOMONTH($A13,-1)+1,$A$5:$A$35,"<="&EOMONTH($A13,0)),posicion,COUNTIFS($A$5:$A13,">="&EOMONTH($A13,-1)+1,$A$5:$A13,"<="&EOMONTH($A13,0)),QUOTIENT(meta,semanas)+IF(posicion<=MOD(meta,semanas),1,0)),"") -> 10 | D13: =IFERROR(LET(meta,SUMIFS(Meta!$Q$5:$Q$16,Meta!$A$5:$A$16,">="&EOMONTH($A13,-1)+1,Meta!$A$5:$A$16,"<="&EOMONTH($A13,0)),semanas,COUNTIFS($A$5:$A$35,">="&EOMONTH($A13,-1)+1,$A$5:$A$35,"<="&EOMONTH($A13,0)),posicion,COUNTIFS($A$5:$A13,">="&EOMONTH($A13,-1)+1,$A$5:$A13,"<="&EOMONTH($A13,0)),QUOTIENT(meta,semanas)+IF(posicion<=MOD(meta,semanas),1,0)),"") -> 4 | E13: =IFERROR(LET(meta,SUMIFS(Meta!$C$5:$C$16,Meta!$A$5:$A$16,">="&EOMONTH($A13,-1)+1,Meta!$A$5:$A$16,"<="&EOMONTH($A13,0)),semanas,COUNTIFS($A$5:$A$35,">="&EOMONTH($A13,-1)+1,$A$5:$A$35,"<="&EOMONTH($A13,0)),posicion,COUNTIFS($A$5:$A13,">="&EOMONTH($A13,-1)+1,$A$5:$A13,"<="&EOMONTH($A13,0)),QUOTIENT(meta,semanas)+IF(posicion<=MOD(meta,semanas),1,0)),"") -> 3 | F13: =IFERROR(SUMIFS(Meta!$B$5:$B$16,Meta!$A$5:$A$16,">="&EOMONTH($A13,-1)+1,Meta!$A$5:$A$16,"<="&EOMONTH($A13,0))/COUNTIFS($A$5:$A$35,">="&EOMONTH($A13,-1)+1,$A$5:$A$35,"<="&EOMONTH($A13,0)),"") -> 100000 | G13: =COUNTIFS(Data_Ventas!$E$2:$E1001,">="&A13,Data_Ventas!$E$2:$E1001,"<="&A13+6) -> 0 | H13: =COUNTIFS(Data_Ventas!$A$2:$A1001,">="&A13,Data_Ventas!$A$2:$A1001,"<="&A13+6,Data_Ventas!$H$2:$H1001,"Visitó proyecto") -> 0 | I13: =COUNTIFS(Data_Ventas!$A$2:$A1001,">="&A13,Data_Ventas!$A$2:$A1001,"<="&A13+6,Data_Ventas!$H$2:$H1001,"Separado") -> 0 | J13: =COUNTIFS(Data_Ventas!$A$2:$A1001,">="&A13,Data_Ventas!$A$2:$A1001,"<="&A13+6,Data_Ventas!$H$2:$H1001,"Venta") -> 1 | K13: =SUMIFS(Data_Ventas!$N$2:$N1001,Data_Ventas!$A$2:$A1001,">="&A13,Data_Ventas!$A$2:$A1001,"<="&A13+6,Data_Ventas!$H$2:$H1001,"Venta") -> 40000 | L13: =IFERROR(K13/F13,"0%") -> 0.4
A14: =A13+7 -> 46278 | B14: =IFERROR(LET(meta,SUMIFS(Meta!$N$5:$N$16,Meta!$A$5:$A$16,">="&EOMONTH($A14,-1)+1,Meta!$A$5:$A$16,"<="&EOMONTH($A14,0)),semanas,COUNTIFS($A$5:$A$35,">="&EOMONTH($A14,-1)+1,$A$5:$A$35,"<="&EOMONTH($A14,0)),posicion,COUNTIFS($A$5:$A14,">="&EOMONTH($A14,-1)+1,$A$5:$A14,"<="&EOMONTH($A14,0)),QUOTIENT(meta,semanas)+IF(posicion<=MOD(meta,semanas),1,0)),"") -> 81 | C14: =IFERROR(LET(meta,SUMIFS(Meta!$P$5:$P$16,Meta!$A$5:$A$16,">="&EOMONTH($A14,-1)+1,Meta!$A$5:$A$16,"<="&EOMONTH($A14,0)),semanas,COUNTIFS($A$5:$A$35,">="&EOMONTH($A14,-1)+1,$A$5:$A$35,"<="&EOMONTH($A14,0)),posicion,COUNTIFS($A$5:$A14,">="&EOMONTH($A14,-1)+1,$A$5:$A14,"<="&EOMONTH($A14,0)),QUOTIENT(meta,semanas)+IF(posicion<=MOD(meta,semanas),1,0)),"") -> 10 | D14: =IFERROR(LET(meta,SUMIFS(Meta!$Q$5:$Q$16,Meta!$A$5:$A$16,">="&EOMONTH($A14,-1)+1,Meta!$A$5:$A$16,"<="&EOMONTH($A14,0)),semanas,COUNTIFS($A$5:$A$35,">="&EOMONTH($A14,-1)+1,$A$5:$A$35,"<="&EOMONTH($A14,0)),posicion,COUNTIFS($A$5:$A14,">="&EOMONTH($A14,-1)+1,$A$5:$A14,"<="&EOMONTH($A14,0)),QUOTIENT(meta,semanas)+IF(posicion<=MOD(meta,semanas),1,0)),"") -> 3 | E14: =IFERROR(LET(meta,SUMIFS(Meta!$C$5:$C$16,Meta!$A$5:$A$16,">="&EOMONTH($A14,-1)+1,Meta!$A$5:$A$16,"<="&EOMONTH($A14,0)),semanas,COUNTIFS($A$5:$A$35,">="&EOMONTH($A14,-1)+1,$A$5:$A$35,"<="&EOMONTH($A14,0)),posicion,COUNTIFS($A$5:$A14,">="&EOMONTH($A14,-1)+1,$A$5:$A14,"<="&EOMONTH($A14,0)),QUOTIENT(meta,semanas)+IF(posicion<=MOD(meta,semanas),1,0)),"") -> 3 | F14: =IFERROR(SUMIFS(Meta!$B$5:$B$16,Meta!$A$5:$A$16,">="&EOMONTH($A14,-1)+1,Meta!$A$5:$A$16,"<="&EOMONTH($A14,0))/COUNTIFS($A$5:$A$35,">="&EOMONTH($A14,-1)+1,$A$5:$A$35,"<="&EOMONTH($A14,0)),"") -> 100000 | G14: =COUNTIFS(Data_Ventas!$E$2:$E1001,">="&A14,Data_Ventas!$E$2:$E1001,"<="&A14+6) -> 0 | H14: =COUNTIFS(Data_Ventas!$A$2:$A1001,">="&A14,Data_Ventas!$A$2:$A1001,"<="&A14+6,Data_Ventas!$H$2:$H1001,"Visitó proyecto") -> 0 | I14: =COUNTIFS(Data_Ventas!$A$2:$A1001,">="&A14,Data_Ventas!$A$2:$A1001,"<="&A14+6,Data_Ventas!$H$2:$H1001,"Separado") -> 0 | J14: =COUNTIFS(Data_Ventas!$A$2:$A1001,">="&A14,Data_Ventas!$A$2:$A1001,"<="&A14+6,Data_Ventas!$H$2:$H1001,"Venta") -> 0 | K14: =SUMIFS(Data_Ventas!$N$2:$N1001,Data_Ventas!$A$2:$A1001,">="&A14,Data_Ventas!$A$2:$A1001,"<="&A14+6,Data_Ventas!$H$2:$H1001,"Venta") -> 0 | L14: =IFERROR(K14/F14,"0%") -> 0
A15: =A14+7 -> 46285 | B15: =IFERROR(LET(meta,SUMIFS(Meta!$N$5:$N$16,Meta!$A$5:$A$16,">="&EOMONTH($A15,-1)+1,Meta!$A$5:$A$16,"<="&EOMONTH($A15,0)),semanas,COUNTIFS($A$5:$A$35,">="&EOMONTH($A15,-1)+1,$A$5:$A$35,"<="&EOMONTH($A15,0)),posicion,COUNTIFS($A$5:$A15,">="&EOMONTH($A15,-1)+1,$A$5:$A15,"<="&EOMONTH($A15,0)),QUOTIENT(meta,semanas)+IF(posicion<=MOD(meta,semanas),1,0)),"") -> 81 | C15: =IFERROR(LET(meta,SUMIFS(Meta!$P$5:$P$16,Meta!$A$5:$A$16,">="&EOMONTH($A15,-1)+1,Meta!$A$5:$A$16,"<="&EOMONTH($A15,0)),semanas,COUNTIFS($A$5:$A$35,">="&EOMONTH($A15,-1)+1,$A$5:$A$35,"<="&EOMONTH($A15,0)),posicion,COUNTIFS($A$5:$A15,">="&EOMONTH($A15,-1)+1,$A$5:$A15,"<="&EOMONTH($A15,0)),QUOTIENT(meta,semanas)+IF(posicion<=MOD(meta,semanas),1,0)),"") -> 10 | D15: =IFERROR(LET(meta,SUMIFS(Meta!$Q$5:$Q$16,Meta!$A$5:$A$16,">="&EOMONTH($A15,-1)+1,Meta!$A$5:$A$16,"<="&EOMONTH($A15,0)),semanas,COUNTIFS($A$5:$A$35,">="&EOMONTH($A15,-1)+1,$A$5:$A$35,"<="&EOMONTH($A15,0)),posicion,COUNTIFS($A$5:$A15,">="&EOMONTH($A15,-1)+1,$A$5:$A15,"<="&EOMONTH($A15,0)),QUOTIENT(meta,semanas)+IF(posicion<=MOD(meta,semanas),1,0)),"") -> 3 | E15: =IFERROR(LET(meta,SUMIFS(Meta!$C$5:$C$16,Meta!$A$5:$A$16,">="&EOMONTH($A15,-1)+1,Meta!$A$5:$A$16,"<="&EOMONTH($A15,0)),semanas,COUNTIFS($A$5:$A$35,">="&EOMONTH($A15,-1)+1,$A$5:$A$35,"<="&EOMONTH($A15,0)),posicion,COUNTIFS($A$5:$A15,">="&EOMONTH($A15,-1)+1,$A$5:$A15,"<="&EOMONTH($A15,0)),QUOTIENT(meta,semanas)+IF(posicion<=MOD(meta,semanas),1,0)),"") -> 2 | F15: =IFERROR(SUMIFS(Meta!$B$5:$B$16,Meta!$A$5:$A$16,">="&EOMONTH($A15,-1)+1,Meta!$A$5:$A$16,"<="&EOMONTH($A15,0))/COUNTIFS($A$5:$A$35,">="&EOMONTH($A15,-1)+1,$A$5:$A$35,"<="&EOMONTH($A15,0)),"") -> 100000 | G15: =COUNTIFS(Data_Ventas!$E$2:$E1001,">="&A15,Data_Ventas!$E$2:$E1001,"<="&A15+6) -> 0 | H15: =COUNTIFS(Data_Ventas!$A$2:$A1001,">="&A15,Data_Ventas!$A$2:$A1001,"<="&A15+6,Data_Ventas!$H$2:$H1001,"Visitó proyecto") -> 0 | I15: =COUNTIFS(Data_Ventas!$A$2:$A1001,">="&A15,Data_Ventas!$A$2:$A1001,"<="&A15+6,Data_Ventas!$H$2:$H1001,"Separado") -> 0 | J15: =COUNTIFS(Data_Ventas!$A$2:$A1001,">="&A15,Data_Ventas!$A$2:$A1001,"<="&A15+6,Data_Ventas!$H$2:$H1001,"Venta") -> 0 | K15: =SUMIFS(Data_Ventas!$N$2:$N1001,Data_Ventas!$A$2:$A1001,">="&A15,Data_Ventas!$A$2:$A1001,"<="&A15+6,Data_Ventas!$H$2:$H1001,"Venta") -> 0 | L15: =IFERROR(K15/F15,"0%") -> 0
A16: =A15+7 -> 46292 | B16: =IFERROR(LET(meta,SUMIFS(Meta!$N$5:$N$16,Meta!$A$5:$A$16,">="&EOMONTH($A16,-1)+1,Meta!$A$5:$A$16,"<="&EOMONTH($A16,0)),semanas,COUNTIFS($A$5:$A$35,">="&EOMONTH($A16,-1)+1,$A$5:$A$35,"<="&EOMONTH($A16,0)),posicion,COUNTIFS($A$5:$A16,">="&EOMONTH($A16,-1)+1,$A$5:$A16,"<="&EOMONTH($A16,0)),QUOTIENT(meta,semanas)+IF(posicion<=MOD(meta,semanas),1,0)),"") -> 81 | C16: =IFERROR(LET(meta,SUMIFS(Meta!$P$5:$P$16,Meta!$A$5:$A$16,">="&EOMONTH($A16,-1)+1,Meta!$A$5:$A$16,"<="&EOMONTH($A16,0)),semanas,COUNTIFS($A$5:$A$35,">="&EOMONTH($A16,-1)+1,$A$5:$A$35,"<="&EOMONTH($A16,0)),posicion,COUNTIFS($A$5:$A16,">="&EOMONTH($A16,-1)+1,$A$5:$A16,"<="&EOMONTH($A16,0)),QUOTIENT(meta,semanas)+IF(posicion<=MOD(meta,semanas),1,0)),"") -> 9 | D16: =IFERROR(LET(meta,SUMIFS(Meta!$Q$5:$Q$16,Meta!$A$5:$A$16,">="&EOMONTH($A16,-1)+1,Meta!$A$5:$A$16,"<="&EOMONTH($A16,0)),semanas,COUNTIFS($A$5:$A$35,">="&EOMONTH($A16,-1)+1,$A$5:$A$35,"<="&EOMONTH($A16,0)),posicion,COUNTIFS($A$5:$A16,">="&EOMONTH($A16,-1)+1,$A$5:$A16,"<="&EOMONTH($A16,0)),QUOTIENT(meta,semanas)+IF(posicion<=MOD(meta,semanas),1,0)),"") -> 3 | E16: =IFERROR(LET(meta,SUMIFS(Meta!$C$5:$C$16,Meta!$A$5:$A$16,">="&EOMONTH($A16,-1)+1,Meta!$A$5:$A$16,"<="&EOMONTH($A16,0)),semanas,COUNTIFS($A$5:$A$35,">="&EOMONTH($A16,-1)+1,$A$5:$A$35,"<="&EOMONTH($A16,0)),posicion,COUNTIFS($A$5:$A16,">="&EOMONTH($A16,-1)+1,$A$5:$A16,"<="&EOMONTH($A16,0)),QUOTIENT(meta,semanas)+IF(posicion<=MOD(meta,semanas),1,0)),"") -> 2 | F16: =IFERROR(SUMIFS(Meta!$B$5:$B$16,Meta!$A$5:$A$16,">="&EOMONTH($A16,-1)+1,Meta!$A$5:$A$16,"<="&EOMONTH($A16,0))/COUNTIFS($A$5:$A$35,">="&EOMONTH($A16,-1)+1,$A$5:$A$35,"<="&EOMONTH($A16,0)),"") -> 100000 | G16: =COUNTIFS(Data_Ventas!$E$2:$E1001,">="&A16,Data_Ventas!$E$2:$E1001,"<="&A16+6) -> 0 | H16: =COUNTIFS(Data_Ventas!$A$2:$A1001,">="&A16,Data_Ventas!$A$2:$A1001,"<="&A16+6,Data_Ventas!$H$2:$H1001,"Visitó proyecto") -> 0 | I16: =COUNTIFS(Data_Ventas!$A$2:$A1001,">="&A16,Data_Ventas!$A$2:$A1001,"<="&A16+6,Data_Ventas!$H$2:$H1001,"Separado") -> 0 | J16: =COUNTIFS(Data_Ventas!$A$2:$A1001,">="&A16,Data_Ventas!$A$2:$A1001,"<="&A16+6,Data_Ventas!$H$2:$H1001,"Venta") -> 0 | K16: =SUMIFS(Data_Ventas!$N$2:$N1001,Data_Ventas!$A$2:$A1001,">="&A16,Data_Ventas!$A$2:$A1001,"<="&A16+6,Data_Ventas!$H$2:$H1001,"Venta") -> 0 | L16: =IFERROR(K16/F16,"0%") -> 0
A17: =A16+7 -> 46299 | B17: =IFERROR(LET(meta,SUMIFS(Meta!$N$5:$N$16,Meta!$A$5:$A$16,">="&EOMONTH($A17,-1)+1,Meta!$A$5:$A$16,"<="&EOMONTH($A17,0)),semanas,COUNTIFS($A$5:$A$35,">="&EOMONTH($A17,-1)+1,$A$5:$A$35,"<="&EOMONTH($A17,0)),posicion,COUNTIFS($A$5:$A17,">="&EOMONTH($A17,-1)+1,$A$5:$A17,"<="&EOMONTH($A17,0)),QUOTIENT(meta,semanas)+IF(posicion<=MOD(meta,semanas),1,0)),"") -> 82 | C17: =IFERROR(LET(meta,SUMIFS(Meta!$P$5:$P$16,Meta!$A$5:$A$16,">="&EOMONTH($A17,-1)+1,Meta!$A$5:$A$16,"<="&EOMONTH($A17,0)),semanas,COUNTIFS($A$5:$A$35,">="&EOMONTH($A17,-1)+1,$A$5:$A$35,"<="&EOMONTH($A17,0)),posicion,COUNTIFS($A$5:$A17,">="&EOMONTH($A17,-1)+1,$A$5:$A17,"<="&EOMONTH($A17,0)),QUOTIENT(meta,semanas)+IF(posicion<=MOD(meta,semanas),1,0)),"") -> 10 | D17: =IFERROR(LET(meta,SUMIFS(Meta!$Q$5:$Q$16,Meta!$A$5:$A$16,">="&EOMONTH($A17,-1)+1,Meta!$A$5:$A$16,"<="&EOMONTH($A17,0)),semanas,COUNTIFS($A$5:$A$35,">="&EOMONTH($A17,-1)+1,$A$5:$A$35,"<="&EOMONTH($A17,0)),posicion,COUNTIFS($A$5:$A17,">="&EOMONTH($A17,-1)+1,$A$5:$A17,"<="&EOMONTH($A17,0)),QUOTIENT(meta,semanas)+IF(posicion<=MOD(meta,semanas),1,0)),"") -> 4 | E17: =IFERROR(LET(meta,SUMIFS(Meta!$C$5:$C$16,Meta!$A$5:$A$16,">="&EOMONTH($A17,-1)+1,Meta!$A$5:$A$16,"<="&EOMONTH($A17,0)),semanas,COUNTIFS($A$5:$A$35,">="&EOMONTH($A17,-1)+1,$A$5:$A$35,"<="&EOMONTH($A17,0)),posicion,COUNTIFS($A$5:$A17,">="&EOMONTH($A17,-1)+1,$A$5:$A17,"<="&EOMONTH($A17,0)),QUOTIENT(meta,semanas)+IF(posicion<=MOD(meta,semanas),1,0)),"") -> 3 | F17: =IFERROR(SUMIFS(Meta!$B$5:$B$16,Meta!$A$5:$A$16,">="&EOMONTH($A17,-1)+1,Meta!$A$5:$A$16,"<="&EOMONTH($A17,0))/COUNTIFS($A$5:$A$35,">="&EOMONTH($A17,-1)+1,$A$5:$A$35,"<="&EOMONTH($A17,0)),"") -> 100000 | G17: =COUNTIFS(Data_Ventas!$E$2:$E1001,">="&A17,Data_Ventas!$E$2:$E1001,"<="&A17+6) -> 0 | H17: =COUNTIFS(Data_Ventas!$A$2:$A1001,">="&A17,Data_Ventas!$A$2:$A1001,"<="&A17+6,Data_Ventas!$H$2:$H1001,"Visitó proyecto") -> 0 | I17: =COUNTIFS(Data_Ventas!$A$2:$A1001,">="&A17,Data_Ventas!$A$2:$A1001,"<="&A17+6,Data_Ventas!$H$2:$H1001,"Separado") -> 0 | J17: =COUNTIFS(Data_Ventas!$A$2:$A1001,">="&A17,Data_Ventas!$A$2:$A1001,"<="&A17+6,Data_Ventas!$H$2:$H1001,"Venta") -> 0 | K17: =SUMIFS(Data_Ventas!$N$2:$N1001,Data_Ventas!$A$2:$A1001,">="&A17,Data_Ventas!$A$2:$A1001,"<="&A17+6,Data_Ventas!$H$2:$H1001,"Venta") -> 0 | L17: =IFERROR(K17/F17,"0%") -> 0
A18: =A17+7 -> 46306 | B18: =IFERROR(LET(meta,SUMIFS(Meta!$N$5:$N$16,Meta!$A$5:$A$16,">="&EOMONTH($A18,-1)+1,Meta!$A$5:$A$16,"<="&EOMONTH($A18,0)),semanas,COUNTIFS($A$5:$A$35,">="&EOMONTH($A18,-1)+1,$A$5:$A$35,"<="&EOMONTH($A18,0)),posicion,COUNTIFS($A$5:$A18,">="&EOMONTH($A18,-1)+1,$A$5:$A18,"<="&EOMONTH($A18,0)),QUOTIENT(meta,semanas)+IF(posicion<=MOD(meta,semanas),1,0)),"") -> 81 | C18: =IFERROR(LET(meta,SUMIFS(Meta!$P$5:$P$16,Meta!$A$5:$A$16,">="&EOMONTH($A18,-1)+1,Meta!$A$5:$A$16,"<="&EOMONTH($A18,0)),semanas,COUNTIFS($A$5:$A$35,">="&EOMONTH($A18,-1)+1,$A$5:$A$35,"<="&EOMONTH($A18,0)),posicion,COUNTIFS($A$5:$A18,">="&EOMONTH($A18,-1)+1,$A$5:$A18,"<="&EOMONTH($A18,0)),QUOTIENT(meta,semanas)+IF(posicion<=MOD(meta,semanas),1,0)),"") -> 10 | D18: =IFERROR(LET(meta,SUMIFS(Meta!$Q$5:$Q$16,Meta!$A$5:$A$16,">="&EOMONTH($A18,-1)+1,Meta!$A$5:$A$16,"<="&EOMONTH($A18,0)),semanas,COUNTIFS($A$5:$A$35,">="&EOMONTH($A18,-1)+1,$A$5:$A$35,"<="&EOMONTH($A18,0)),posicion,COUNTIFS($A$5:$A18,">="&EOMONTH($A18,-1)+1,$A$5:$A18,"<="&EOMONTH($A18,0)),QUOTIENT(meta,semanas)+IF(posicion<=MOD(meta,semanas),1,0)),"") -> 3 | E18: =IFERROR(LET(meta,SUMIFS(Meta!$C$5:$C$16,Meta!$A$5:$A$16,">="&EOMONTH($A18,-1)+1,Meta!$A$5:$A$16,"<="&EOMONTH($A18,0)),semanas,COUNTIFS($A$5:$A$35,">="&EOMONTH($A18,-1)+1,$A$5:$A$35,"<="&EOMONTH($A18,0)),posicion,COUNTIFS($A$5:$A18,">="&EOMONTH($A18,-1)+1,$A$5:$A18,"<="&EOMONTH($A18,0)),QUOTIENT(meta,semanas)+IF(posicion<=MOD(meta,semanas),1,0)),"") -> 3 | F18: =IFERROR(SUMIFS(Meta!$B$5:$B$16,Meta!$A$5:$A$16,">="&EOMONTH($A18,-1)+1,Meta!$A$5:$A$16,"<="&EOMONTH($A18,0))/COUNTIFS($A$5:$A$35,">="&EOMONTH($A18,-1)+1,$A$5:$A$35,"<="&EOMONTH($A18,0)),"") -> 100000 | G18: =COUNTIFS(Data_Ventas!$E$2:$E1001,">="&A18,Data_Ventas!$E$2:$E1001,"<="&A18+6) -> 0 | H18: =COUNTIFS(Data_Ventas!$A$2:$A1001,">="&A18,Data_Ventas!$A$2:$A1001,"<="&A18+6,Data_Ventas!$H$2:$H1001,"Visitó proyecto") -> 0 | I18: =COUNTIFS(Data_Ventas!$A$2:$A1001,">="&A18,Data_Ventas!$A$2:$A1001,"<="&A18+6,Data_Ventas!$H$2:$H1001,"Separado") -> 0 | J18: =COUNTIFS(Data_Ventas!$A$2:$A1001,">="&A18,Data_Ventas!$A$2:$A1001,"<="&A18+6,Data_Ventas!$H$2:$H1001,"Venta") -> 0 | K18: =SUMIFS(Data_Ventas!$N$2:$N1001,Data_Ventas!$A$2:$A1001,">="&A18,Data_Ventas!$A$2:$A1001,"<="&A18+6,Data_Ventas!$H$2:$H1001,"Venta") -> 0 | L18: =IFERROR(K18/F18,"0%") -> 0
A19: =A18+7 -> 46313 | B19: =IFERROR(LET(meta,SUMIFS(Meta!$N$5:$N$16,Meta!$A$5:$A$16,">="&EOMONTH($A19,-1)+1,Meta!$A$5:$A$16,"<="&EOMONTH($A19,0)),semanas,COUNTIFS($A$5:$A$35,">="&EOMONTH($A19,-1)+1,$A$5:$A$35,"<="&EOMONTH($A19,0)),posicion,COUNTIFS($A$5:$A19,">="&EOMONTH($A19,-1)+1,$A$5:$A19,"<="&EOMONTH($A19,0)),QUOTIENT(meta,semanas)+IF(posicion<=MOD(meta,semanas),1,0)),"") -> 81 | C19: =IFERROR(LET(meta,SUMIFS(Meta!$P$5:$P$16,Meta!$A$5:$A$16,">="&EOMONTH($A19,-1)+1,Meta!$A$5:$A$16,"<="&EOMONTH($A19,0)),semanas,COUNTIFS($A$5:$A$35,">="&EOMONTH($A19,-1)+1,$A$5:$A$35,"<="&EOMONTH($A19,0)),posicion,COUNTIFS($A$5:$A19,">="&EOMONTH($A19,-1)+1,$A$5:$A19,"<="&EOMONTH($A19,0)),QUOTIENT(meta,semanas)+IF(posicion<=MOD(meta,semanas),1,0)),"") -> 10 | D19: =IFERROR(LET(meta,SUMIFS(Meta!$Q$5:$Q$16,Meta!$A$5:$A$16,">="&EOMONTH($A19,-1)+1,Meta!$A$5:$A$16,"<="&EOMONTH($A19,0)),semanas,COUNTIFS($A$5:$A$35,">="&EOMONTH($A19,-1)+1,$A$5:$A$35,"<="&EOMONTH($A19,0)),posicion,COUNTIFS($A$5:$A19,">="&EOMONTH($A19,-1)+1,$A$5:$A19,"<="&EOMONTH($A19,0)),QUOTIENT(meta,semanas)+IF(posicion<=MOD(meta,semanas),1,0)),"") -> 3 | E19: =IFERROR(LET(meta,SUMIFS(Meta!$C$5:$C$16,Meta!$A$5:$A$16,">="&EOMONTH($A19,-1)+1,Meta!$A$5:$A$16,"<="&EOMONTH($A19,0)),semanas,COUNTIFS($A$5:$A$35,">="&EOMONTH($A19,-1)+1,$A$5:$A$35,"<="&EOMONTH($A19,0)),posicion,COUNTIFS($A$5:$A19,">="&EOMONTH($A19,-1)+1,$A$5:$A19,"<="&EOMONTH($A19,0)),QUOTIENT(meta,semanas)+IF(posicion<=MOD(meta,semanas),1,0)),"") -> 2 | F19: =IFERROR(SUMIFS(Meta!$B$5:$B$16,Meta!$A$5:$A$16,">="&EOMONTH($A19,-1)+1,Meta!$A$5:$A$16,"<="&EOMONTH($A19,0))/COUNTIFS($A$5:$A$35,">="&EOMONTH($A19,-1)+1,$A$5:$A$35,"<="&EOMONTH($A19,0)),"") -> 100000 | G19: =COUNTIFS(Data_Ventas!$E$2:$E1001,">="&A19,Data_Ventas!$E$2:$E1001,"<="&A19+6) -> 0 | H19: =COUNTIFS(Data_Ventas!$A$2:$A1001,">="&A19,Data_Ventas!$A$2:$A1001,"<="&A19+6,Data_Ventas!$H$2:$H1001,"Visitó proyecto") -> 0 | I19: =COUNTIFS(Data_Ventas!$A$2:$A1001,">="&A19,Data_Ventas!$A$2:$A1001,"<="&A19+6,Data_Ventas!$H$2:$H1001,"Separado") -> 0 | J19: =COUNTIFS(Data_Ventas!$A$2:$A1001,">="&A19,Data_Ventas!$A$2:$A1001,"<="&A19+6,Data_Ventas!$H$2:$H1001,"Venta") -> 0 | K19: =SUMIFS(Data_Ventas!$N$2:$N1001,Data_Ventas!$A$2:$A1001,">="&A19,Data_Ventas!$A$2:$A1001,"<="&A19+6,Data_Ventas!$H$2:$H1001,"Venta") -> 0 | L19: =IFERROR(K19/F19,"0%") -> 0
A20: =A19+7 -> 46320 | B20: =IFERROR(LET(meta,SUMIFS(Meta!$N$5:$N$16,Meta!$A$5:$A$16,">="&EOMONTH($A20,-1)+1,Meta!$A$5:$A$16,"<="&EOMONTH($A20,0)),semanas,COUNTIFS($A$5:$A$35,">="&EOMONTH($A20,-1)+1,$A$5:$A$35,"<="&EOMONTH($A20,0)),posicion,COUNTIFS($A$5:$A20,">="&EOMONTH($A20,-1)+1,$A$5:$A20,"<="&EOMONTH($A20,0)),QUOTIENT(meta,semanas)+IF(posicion<=MOD(meta,semanas),1,0)),"") -> 81 | C20: =IFERROR(LET(meta,SUMIFS(Meta!$P$5:$P$16,Meta!$A$5:$A$16,">="&EOMONTH($A20,-1)+1,Meta!$A$5:$A$16,"<="&EOMONTH($A20,0)),semanas,COUNTIFS($A$5:$A$35,">="&EOMONTH($A20,-1)+1,$A$5:$A$35,"<="&EOMONTH($A20,0)),posicion,COUNTIFS($A$5:$A20,">="&EOMONTH($A20,-1)+1,$A$5:$A20,"<="&EOMONTH($A20,0)),QUOTIENT(meta,semanas)+IF(posicion<=MOD(meta,semanas),1,0)),"") -> 9 | D20: =IFERROR(LET(meta,SUMIFS(Meta!$Q$5:$Q$16,Meta!$A$5:$A$16,">="&EOMONTH($A20,-1)+1,Meta!$A$5:$A$16,"<="&EOMONTH($A20,0)),semanas,COUNTIFS($A$5:$A$35,">="&EOMONTH($A20,-1)+1,$A$5:$A$35,"<="&EOMONTH($A20,0)),posicion,COUNTIFS($A$5:$A20,">="&EOMONTH($A20,-1)+1,$A$5:$A20,"<="&EOMONTH($A20,0)),QUOTIENT(meta,semanas)+IF(posicion<=MOD(meta,semanas),1,0)),"") -> 3 | E20: =IFERROR(LET(meta,SUMIFS(Meta!$C$5:$C$16,Meta!$A$5:$A$16,">="&EOMONTH($A20,-1)+1,Meta!$A$5:$A$16,"<="&EOMONTH($A20,0)),semanas,COUNTIFS($A$5:$A$35,">="&EOMONTH($A20,-1)+1,$A$5:$A$35,"<="&EOMONTH($A20,0)),posicion,COUNTIFS($A$5:$A20,">="&EOMONTH($A20,-1)+1,$A$5:$A20,"<="&EOMONTH($A20,0)),QUOTIENT(meta,semanas)+IF(posicion<=MOD(meta,semanas),1,0)),"") -> 2 | F20: =IFERROR(SUMIFS(Meta!$B$5:$B$16,Meta!$A$5:$A$16,">="&EOMONTH($A20,-1)+1,Meta!$A$5:$A$16,"<="&EOMONTH($A20,0))/COUNTIFS($A$5:$A$35,">="&EOMONTH($A20,-1)+1,$A$5:$A$35,"<="&EOMONTH($A20,0)),"") -> 100000 | G20: =COUNTIFS(Data_Ventas!$E$2:$E1001,">="&A20,Data_Ventas!$E$2:$E1001,"<="&A20+6) -> 0 | H20: =COUNTIFS(Data_Ventas!$A$2:$A1001,">="&A20,Data_Ventas!$A$2:$A1001,"<="&A20+6,Data_Ventas!$H$2:$H1001,"Visitó proyecto") -> 0 | I20: =COUNTIFS(Data_Ventas!$A$2:$A1001,">="&A20,Data_Ventas!$A$2:$A1001,"<="&A20+6,Data_Ventas!$H$2:$H1001,"Separado") -> 0 | J20: =COUNTIFS(Data_Ventas!$A$2:$A1001,">="&A20,Data_Ventas!$A$2:$A1001,"<="&A20+6,Data_Ventas!$H$2:$H1001,"Venta") -> 0 | K20: =SUMIFS(Data_Ventas!$N$2:$N1001,Data_Ventas!$A$2:$A1001,">="&A20,Data_Ventas!$A$2:$A1001,"<="&A20+6,Data_Ventas!$H$2:$H1001,"Venta") -> 0 | L20: =IFERROR(K20/F20,"0%") -> 0
A21: =A20+7 -> 46327 | B21: =IFERROR(LET(meta,SUMIFS(Meta!$N$5:$N$16,Meta!$A$5:$A$16,">="&EOMONTH($A21,-1)+1,Meta!$A$5:$A$16,"<="&EOMONTH($A21,0)),semanas,COUNTIFS($A$5:$A$35,">="&EOMONTH($A21,-1)+1,$A$5:$A$35,"<="&EOMONTH($A21,0)),posicion,COUNTIFS($A$5:$A21,">="&EOMONTH($A21,-1)+1,$A$5:$A21,"<="&EOMONTH($A21,0)),QUOTIENT(meta,semanas)+IF(posicion<=MOD(meta,semanas),1,0)),"") -> 65 | C21: =IFERROR(LET(meta,SUMIFS(Meta!$P$5:$P$16,Meta!$A$5:$A$16,">="&EOMONTH($A21,-1)+1,Meta!$A$5:$A$16,"<="&EOMONTH($A21,0)),semanas,COUNTIFS($A$5:$A$35,">="&EOMONTH($A21,-1)+1,$A$5:$A$35,"<="&EOMONTH($A21,0)),posicion,COUNTIFS($A$5:$A21,">="&EOMONTH($A21,-1)+1,$A$5:$A21,"<="&EOMONTH($A21,0)),QUOTIENT(meta,semanas)+IF(posicion<=MOD(meta,semanas),1,0)),"") -> 8 | D21: =IFERROR(LET(meta,SUMIFS(Meta!$Q$5:$Q$16,Meta!$A$5:$A$16,">="&EOMONTH($A21,-1)+1,Meta!$A$5:$A$16,"<="&EOMONTH($A21,0)),semanas,COUNTIFS($A$5:$A$35,">="&EOMONTH($A21,-1)+1,$A$5:$A$35,"<="&EOMONTH($A21,0)),posicion,COUNTIFS($A$5:$A21,">="&EOMONTH($A21,-1)+1,$A$5:$A21,"<="&EOMONTH($A21,0)),QUOTIENT(meta,semanas)+IF(posicion<=MOD(meta,semanas),1,0)),"") -> 3 | E21: =IFERROR(LET(meta,SUMIFS(Meta!$C$5:$C$16,Meta!$A$5:$A$16,">="&EOMONTH($A21,-1)+1,Meta!$A$5:$A$16,"<="&EOMONTH($A21,0)),semanas,COUNTIFS($A$5:$A$35,">="&EOMONTH($A21,-1)+1,$A$5:$A$35,"<="&EOMONTH($A21,0)),posicion,COUNTIFS($A$5:$A21,">="&EOMONTH($A21,-1)+1,$A$5:$A21,"<="&EOMONTH($A21,0)),QUOTIENT(meta,semanas)+IF(posicion<=MOD(meta,semanas),1,0)),"") -> 2 | F21: =IFERROR(SUMIFS(Meta!$B$5:$B$16,Meta!$A$5:$A$16,">="&EOMONTH($A21,-1)+1,Meta!$A$5:$A$16,"<="&EOMONTH($A21,0))/COUNTIFS($A$5:$A$35,">="&EOMONTH($A21,-1)+1,$A$5:$A$35,"<="&EOMONTH($A21,0)),"") -> 80000 | G21: =COUNTIFS(Data_Ventas!$E$2:$E1001,">="&A21,Data_Ventas!$E$2:$E1001,"<="&A21+6) -> 0 | H21: =COUNTIFS(Data_Ventas!$A$2:$A1001,">="&A21,Data_Ventas!$A$2:$A1001,"<="&A21+6,Data_Ventas!$H$2:$H1001,"Visitó proyecto") -> 0 | I21: =COUNTIFS(Data_Ventas!$A$2:$A1001,">="&A21,Data_Ventas!$A$2:$A1001,"<="&A21+6,Data_Ventas!$H$2:$H1001,"Separado") -> 0 | J21: =COUNTIFS(Data_Ventas!$A$2:$A1001,">="&A21,Data_Ventas!$A$2:$A1001,"<="&A21+6,Data_Ventas!$H$2:$H1001,"Venta") -> 0 | K21: =SUMIFS(Data_Ventas!$N$2:$N1001,Data_Ventas!$A$2:$A1001,">="&A21,Data_Ventas!$A$2:$A1001,"<="&A21+6,Data_Ventas!$H$2:$H1001,"Venta") -> 0 | L21: =IFERROR(K21/F21,"0%") -> 0
